Workbook

Sheet Rekapitulace stavby
A1: Export VZ | D1: List obsahuje: | K1: 1) Rekapitulace stavby | W1: 2) Rekapitulace objektů stavby a soupisů prací | BA1: 3.0 | BT1: False | BU1: False | BV1: {6212bf4d-2552-47a0-ba0b-b6d5353c258d}
AR2: >> skryté sloupce << | BS2: 0,1 | BT2: 21
BS3: 0,01 | BT3: 15
D4: REKAPITULACE STAVBY | AS4: v --- níže se nacházejí doplnkové a pomocné údaje k sestavám --- v | BE4: Návod na vyplnění | BS4: 0,001
D5: Kód: | K5: 2018_10_26 | BE5: Měnit lze pouze buňky se žlutým podbarvením!_x000D_ _x000D_ 1) v Rekapitulaci stavby vyplňte údaje o Uchazeči (přenesou se do ostatních sestav i v jiných listech)_x000D_ _x000D_ 2) na vybraných listech vyplňte v sestavě Soupis prací ceny u položek_x000D_ _x000D_ Podrobnosti k vyplnění naleznete na poslední záložce s Pokyny pro vyplnění | BS5: 0,1
D6: Stavba: | K6: Akce Pasohlávky | BS6: 0,1
D7: KSO: | AK7: CC-CZ: | BS7: 0,1
D8: Místo: | K8: Pasohlávky | AK8: Datum: | AN8: 26. 10. 2018 | BS8: 0,1
BS9: 0,1
D10: Zadavatel: | AK10: IČ: | BS10: 0,1
E11: UNIFICA a.s., Příkop 834/8, 602 00 Brno | AK11: DIČ: | BS11: 0,1
BS12: 0,1
D13: Uchazeč: | AK13: IČ: | AN13: 292 22 745 | BS13: 0,1
E14: LP Staving s.r.o. | AK14: DIČ: | AN14: CZ29222745 | BS14: 0,1
BS15: False
D16: Projektant: | AK16: IČ: | BS16: False
E17: Ing. Arch. Pavel Jura | AK17: DIČ: | BS17: True
BS18: 0,01
D19: Poznámka: | BS19: 0,01
BS20: True
D23: Cena bez DPH | AK23: =ROUND(AG51,2) -> 11088857
L25: Sazba daně | W25: Základ daně | AK25: Výše daně
D26: DPH | F26: základní | L26: 0.21 | W26: =ROUND(AZ51,2) -> 11088857 | AK26: =ROUND(AV51,2) -> 2328660.1
F27: snížená | L27: 0.15 | W27: =ROUND(BA51,2) -> 0 | AK27: =ROUND(AW51,2) -> 0
F28: zákl. přenesená | L28: 0.21 | W28: =ROUND(BB51,2) -> 0 | AK28: 0
F29: sníž. přenesená | L29: 0.15 | W29: =ROUND(BC51,2) -> 0 | AK29: 0
F30: nulová | L30: 0 | W30: =ROUND(BD51,2) -> 0 | AK30: 0
D32: Cena s DPH | T32: v | X32: CZK | AK32: =SUM(AK23:AK30) -> 13417518
C39: REKAPITULACE OBJEKTŮ STAVBY A SOUPISŮ PRACÍ
C41: Kód: | L41: =K5 -> 2018_10_26
C42: Stavba: | L42: =K6 -> Akce Pasohlávky
C44: Místo: | L44: =IF(K8="","",K8) -> Pasohlávky | AI44: Datum: | AM44: =IF(AN8= "","",AN8) -> 26. 10. 2018
C46: Zadavatel: | L46: =IF(E11= "","",E11) -> UNIFICA a.s., Příkop 834/8, 602 00 Brno | AI46: Projektant: | AM46: =IF(E17="","",E17) -> Ing. Arch. Pavel Jura | AS46: Informatívní údaje z listů zakázek
C47: Uchazeč: | L47: =IF(E14= "Vyplň údaj","",E14) -> LP Staving s.r.o.
C49: Kód | I49: Objekt, Soupis prací | AG49: Cena bez DPH [CZK] | AN49: Cena s DPH [CZK] | AQ49: Typ | AS49: z toho Ostat._x000D_ náklady [CZK] | AT49: DPH [CZK] | AU49: Normohodiny [h] | AV49: DPH základní [CZK] | AW49: DPH snížená [CZK] | AX49: DPH základní přenesená_x000D_ [CZK] | AY49: DPH snížená přenesená_x000D_ [CZK] | AZ49: Základna_x000D_ DPH základní | BA49: Základna_x000D_ DPH snížená | BB49: Základna_x000D_ DPH zákl. přenesená | BC49: Základna_x000D_ DPH sníž. přenesená | BD49: Základna_x000D_ DPH nulová
C51: Náklady stavby celkem | AG51: =ROUND(SUM(AG52:AG52),2) -> 11088857 | AN51: =SUM(AG51,AT51) -> 13417518 | AS51: =ROUND(SUM(AS52:AS52),2) -> 0 | AT51: =ROUND(SUM(AV51:AW51),2) -> 2328660.1 | AU51: =ROUND(SUM(AU52:AU52),5) -> 0 | AV51: =ROUND(AZ51*L26,2) -> 2328660.1 | AW51: =ROUND(BA51*L27,2) -> 0 | AX51: =ROUND(BB51*L26,2) -> 0 | AY51: =ROUND(BC51*L27,2) -> 0 | AZ51: =ROUND(SUM(AZ52:AZ52),2) -> 11088857 | BA51: =ROUND(SUM(BA52:BA52),2) -> 0 | BB51: =ROUND(SUM(BB52:BB52),2) -> 0 | BC51: =ROUND(SUM(BC52:BC52),2) -> 0 | BD51: =ROUND(SUM(BD52:BD52),2) -> 0 | BS51: D | BT51: 0 | BU51: ###NOIMPORT### | BV51: IMPORT | BW51: {6212bf4d-2552-47a0-ba0b-b6d5353c258d} | BX51: {00000000-0000-0000-0000-000000000000}
A52: / | D52: Bytový dům | J52: Nájemní bydlení pro seniory Pasohlávky - bytový dům | AG52: ='Bytový dům - Nájemní bydl...'!J27 -> 11088857 | AN52: =AG52*1.21 -> 13417518 | AQ52: STA | AS52: 0 | AT52: =ROUND(SUM(AV52:AW52),2) -> 2328660.1 | AU52: ='Bytový dům - Nájemní bydl...'!P101 -> 0 | AV52: ='Bytový dům - Nájemní bydl...'!J30 -> 2328660.1 | AW52: ='Bytový dům - Nájemní bydl...'!J31 -> 0 | AX52: ='Bytový dům - Nájemní bydl...'!J32 -> 0 | AY52: ='Bytový dům - Nájemní bydl...'!J33 -> 0 | AZ52: ='Bytový dům - Nájemní bydl...'!F30 -> 11088857 | BA52: ='Bytový dům - Nájemní bydl...'!F31 -> 0 | BB52: ='Bytový dům - Nájemní bydl...'!F32 -> 0 | BC52: ='Bytový dům - Nájemní bydl...'!F33 -> 0 | BD52: ='Bytový dům - Nájemní bydl...'!F34 -> 0 | BT52: 1 | BV52: IMPORT | BW52: {559dd78e-0e69-4e0c-8963-30de3dd20e1c} | BX52: {6212bf4d-2552-47a0-ba0b-b6d5353c258d} | CM52: 2

Sheet Bytový dům - Nájemní bydl...
D1: List obsahuje: | F1: 1) Krycí list soupisu | G1: 2) Rekapitulace | J1: 3) Soupis prací | K1: Zpět na list: | L1: Rekapitulace stavby
L2: >> skryté sloupce << | AT2: {559dd78e-0e69-4e0c-8963-30de3dd20e1c}
AT3: 2
D4: KRYCÍ LIST SOUPISU | M4: v --- níže se nacházejí doplnkové a pomocné údaje k sestavám --- v | AT4: False
D6: Stavba:
E7: ='Rekapitulace stavby'!K6 -> Akce Pasohlávky
D8: Objekt:
E9: Bytový dům - Nájemní bydlení pro seniory Pasohlávky - bytový dům
D11: KSO: | I11: CC-CZ:
D12: Místo: | F12: Pasohlávky | I12: Datum: | J12: ='Rekapitulace stavby'!AN8 -> 26. 10. 2018
D14: Zadavatel: | I14: IČ:
E15: UNIFICA a.s., Příkop 834/8, 602 00 Brno | I15: DIČ:
D17: Uchazeč: | I17: IČ: | J17: =IF('Rekapitulace stavby'!AN13="Vyplň údaj","",IF('Rekapitulace stavby'!AN13="","",'Rekapitulace stavby'!AN13)) -> 292 22 745
E18: =IF('Rekapitulace stavby'!E14="Vyplň údaj","",IF('Rekapitulace stavby'!E14="","",'Rekapitulace stavby'!E14)) -> LP Staving s.r.o. | I18: DIČ: | J18: =IF('Rekapitulace stavby'!AN14="Vyplň údaj","",IF('Rekapitulace stavby'!AN14="","",'Rekapitulace stavby'!AN14)) -> CZ29222745
D20: Projektant: | I20: IČ:
E21: Ing. Arch. Pavel Jura | I21: DIČ:
D23: Poznámka:
D27: Cena bez DPH | J27: =ROUND(J101,2) -> 11088857
F29: Základ daně | I29: Sazba daně | J29: Výše daně
D30: DPH | E30: základní | F30: =J27 -> 11088857 | I30: 0.21 | J30: =F30*0.21 -> 2328660.1
E31: snížená | F31: =ROUND(SUM(BF101:BF911), 2) -> 0 | I31: 0.15 | J31: =ROUND(ROUND((SUM(BF101:BF911)), 2)*I31, 2) -> 0
E32: zákl. přenesená | F32: =ROUND(SUM(BG101:BG911), 2) -> 0 | I32: 0.21 | J32: 0
E33: sníž. přenesená | F33: =ROUND(SUM(BH101:BH911), 2) -> 0 | I33: 0.15 | J33: 0
E34: nulová | F34: =ROUND(SUM(BI101:BI911), 2) -> 0 | I34: 0 | J34: 0
D36: Cena s DPH | G36: v | H36: CZK | J36: =SUM(J27:J34) -> 13417518
C42: REKAPITULACE ČLENĚNÍ SOUPISU PRACÍ
C44: Stavba:
E45: =E7 -> Akce Pasohlávky
C46: Objekt:
E47: =E9 -> Bytový dům - Nájemní bydlení pro seniory Pasohlávky - bytový dům
C49: Místo: | F49: =F12 -> Pasohlávky | I49: Datum: | J49: =IF(J12="","",J12) -> 26. 10. 2018
C51: Zadavatel: | F51: =E15 -> UNIFICA a.s., Příkop 834/8, 602 00 Brno | I51: Projektant: | J51: =E21 -> Ing. Arch. Pavel Jura
C52: Uchazeč: | F52: =IF(E18="","",E18) -> LP Staving s.r.o.
C54: Kód dílu - Popis | J54: Cena celkem [CZK]
C56: Náklady soupisu celkem | J56: =J101 -> 11088857 | AU56: -1
D57: HSV - Práce a dodávky HSV | J57: =SUM(J58:J64) -> 3898781
D58: 1 - Zemní práce | J58: =J103 -> 125236.54
D59: 2 - Zakládání | J59: =J117 -> 266368.9
D60: 3 - Svislé a kompletní konstrukce | J60: =J141 -> 943588.63
D61: 4 - Vodorovné konstrukce | J61: =J196 -> 1123782.5
...

Sheet Pokyny pro vyplnění
C3: Struktura údajů, formát souboru a metodika pro zpracování
C4: Struktura
C6: Soubor je složen ze záložky Rekapitulace stavby a záložek s názvem soupisu prací pro jednotlivé objekty ve formátu XLSX. Každá ze záložek přitom obsahuje
C7: ještě samostatné sestavy vymezené orámovaním a nadpisem sestavy.
C9: Rekapitulace stavby obsahuje sestavu Rekapitulace stavby a Rekapitulace objektů stavby a soupisů prací.
D10: V sestavě Rekapitulace stavby jsou uvedeny informace identifikující předmět veřejné zakázky na stavební práce, KSO, CC-CZ, CZ-CPV, CZ-CPA a rekapitulaci
D11: celkové nabídkové ceny uchazeče.
D13: V sestavě Rekapitulace objektů stavby a soupisů prací je uvedena rekapitulace stavebních objektů, inženýrských objektů, provozních souborů,
D14: vedlejších a ostatních nákladů a ostatních nákladů s rekapitulací nabídkové ceny za jednotlivé soupisy prací. Na základě údaje Typ je možné
D15: identifikovat, zda se jedná o objekt nebo soupis prací pro daný objekt:
E16: STA | F16: Stavební objekt pozemní
E17: ING | F17: Stavební objekt inženýrský
E18: PRO | F18: Provozní soubor
E19: VON | F19: Vedlejší a ostatní náklady
E20: OST | F20: Ostatní
E21: Soupis | F21: Soupis prací pro daný typ objektu
C23: Soupis prací pro jednotlivé objekty obsahuje sestavy Krycí list soupisu, Rekapitulace členění soupisu prací, Soupis prací. Za soupis prací může být považován
C24: i objekt stavby v případě, že neobsahuje podřízenou zakázku.
D25: Krycí list soupisu obsahuje rekapitulaci informací o předmětu veřejné zakázky ze sestavy Rekapitulace stavby, informaci o zařazení objektu do KSO,
D26: CC-CZ, CZ-CPV, CZ-CPA a rekapitulaci celkové nabídkové ceny uchazeče za aktuální soupis prací.
D28: Rekapitulace členění soupisu prací obsahuje rekapitulaci soupisu prací ve všech úrovních členění soupisu tak, jak byla tato členění použita (např.
D29: stavební díly, funkční díly, případně jiné členění) s rekapitulací nabídkové ceny.
D31: Soupis prací obsahuje položky veškerých stavebních nebo montážních prací, dodávek materiálů a služeb nezbytných pro zhotovení stavebního objektu,
D32: inženýrského objektu, provozního souboru, vedlejších a ostatních nákladů.
D33: Pro položky soupisu prací se zobrazují následující informace:
E34: PČ | G34: Pořadové číslo položky v aktuálním soupisu
E35: TYP | G35: Typ položky: K - konstrukce, M - materiál, PP - plný popis, PSC - poznámka k souboru cen, P - poznámka k položce, VV - výkaz výměr
E36: Kód | G36: Kód položky
E37: Popis | G37: Zkrácený popis položky
E38: MJ | G38: Měrná jednotka položky
E39: Množství | G39: Množství v měrné jednotce
E40: J.cena | G40: Jednotková cena položky. Zadaní může obsahovat namísto J.ceny sloupce J.materiál a J.montáž, jejichž součet definuje
G41: J.cenu položky.
E42: Cena celkem | G42: Celková cena položky daná jako součin množství a j.ceny
E43: Cenová soustava | G43: Příslušnost položky do cenové soustavy
D45: Ke každé položce soupisu prací se na samostatných řádcích může zobrazovat:
E46: Plný popis položky
E47: Poznámka k souboru cen a poznámka zadavatele
E48: Výkaz výměr
D49: Pokud je k řádku výkazu výměr evidovaný údaj ve sloupci Kód, jedná se o definovaný odkaz, na který se může odvolávat výkaz výměr z jiné položky.
...
