Workbook

Sheet Krycí list
A1: CENOVÁ NABÍDKA
A3: Zadavatel: | B3: Konderla Development, s.r.o. | C3: Zhotovitel: | D3: PS BRNO, s.r.o.
B4: Příkop 843/4 | D4: Vídeňská 153/119b
B5: 602 00 Brno | D5: 619 00 Brno
A6: Vyřizuje: Tel.: e-mail: | B6: Roman Červený | C6: Vyřizuje: Tel.: e-mail:
B7: 737867716
B8: cerveny@konderla.eu
C9: Zpracoval: Tel.: e-mail: | D9: ing. Radek Černohorský
C10: Tel.: | D10: 737256124
C11: e-mail: | D11: cernohorsky@ps-brno.cz
A12: Číslo nabídky: | C12: Datum: | D12: 45754
A15: NÁZEV AKCE :
A17: RC Zone Přerov
A21: REKAPITULACE NÁKLADŮ :
A22: HTÚ | D22: =Rekapitulace!C7 -> 53680806
A23: Komunikace | D23: =Rekapitulace!C18 -> 64178987
A24: Splašková kanalizace | D24: =Rekapitulace!C28 -> 10385101
A25: Dešťová kanalizace | D25: =Rekapitulace!C36 -> 41767745
A26: Zaolejovaná kanalizace | D26: =Rekapitulace!C52 -> 27412256
A27: Vodovod | D27: =Rekapitulace!C65 -> 27664222
A28: Požární vodovod | D28: =Rekapitulace!C76 -> 6717135.6
A29: Venkovní elektroinstalace | D29: =Rekapitulace!C82 -> 6556107.1
A30: Areálové rozvody VN a trafostanice | D30: =Rekapitulace!C89 -> 15253301
A31: Hala PR01 | D31: =Rekapitulace!C94 -> 86660416
A32: Hala PR02 | D32: =Rekapitulace!C105 -> 75885186
A33: Hala PR03 | D33: =Rekapitulace!C114 -> 55522073
A34: SHZ | D34: =Rekapitulace!C124 -> 10258992
A35: Prefa konstrukce | D35: =Rekapitulace!C133 -> 88315097
A36: PD - v rozsahu dle VV | D36: 2431980
A37: VRN - v rozsahu dle VV | D37: 7112590
A38: CELKEM ZA OBJEKT: | D38: =SUM(D22:D37) -> 5.79802e+08
A41: POZNÁMKA:
A54: PŘÍLOHY: | B54: Položkový rozpočet

Sheet Rekapitulace
A1: ='Krycí list'!A17 -> RC Zone Přerov
A3: ='Krycí list'!D12 -> 45754
A4: Pozice | B4: Popis | C4: Cena | D4: Poznámky
A5: 1 | B5: Venkovní objekty | C5: =C7+C18+C28+C36+C52+C65+C76+C82+C89 -> 2.5361566e+08
A7: 1.1 | B7: HTÚ (SO 1000) | C7: =SUM(C8:C16) -> 53680806
B8: Demolice a přípava staveniště | C8: 8315200.4
B9: Příprava podloží / pláně | C9: 8859969.8
B10: Sanace podloží pod objekty, komunikacemi a zpev. plochami | C10: 15398328
B11: Odvodnění pláně | C11: 675366
B12: Zhutněný násyp pod objektem (zeminová deska) | C12: 16158204
B13: Dočasně zpevněné manipulační plochy | C13: 1002260.2
B14: Tepelná izolace | C14: 316596.1
B15: Chráničky | C15: 59730
B16: Ostatní | C16: 2895152
A18: 1.2 | B18: Komunikace | C18: =SUM(C19:C26) -> 64178987
B19: Komunikace a zpevněné plochy - část 1 (SO 1100.1) | C19: 5403622.1
B20: Komunikace a zpevněné plochy - část 2 (SO 1100.2) | C20: 2373198.4
B21: Komunikace a zpevněné plochy - část 3 (SO 1100.3) | C21: 6378837.2
B22: Komunikace a zpevněné plochy - část 4 (SO 1100.4) | C22: 8613104.8
B23: Komunikace a zpevněné plochy - část 5 (SO 1100.5) | C23: 12094721
B24: Komunikace a zpevněné plochy - část 6 (SO 1100.6) | C24: 17308168
B25: Komunikace a zpevněné plochy - část 7 (SO 1100.7) | C25: 10953775
B26: Komunikace a zpevněné plochy - část 8 (SO 1100.8) | C26: 1053561.4
A28: 1.3 | B28: Splašková kanalizace | C28: =SUM(C29:C34) -> 10385101
B29: Splašková kanalizace - přípojka (SO 1200.1) | C29: 80736.78
B30: Splašková kanalizace - ČS + výtlak (SO 1200.2) | C30: 4571565
B31: Splašková kanalizace – areál společná (SO 1200.3) | C31: 2236369.4
B32: Splašková kanalizace - areál PR 01 (SO 1200.10) | C32: 1458678.2
B33: Splašková kanalizace - areál PR 02 (SO 1200.20) | C33: 552585.67
B34: Splašková kanalizace - areál PR 03 (SO 1200.30) | C34: 1485165.7
A36: 1.4 | B36: Dešťová kanalizace | C36: =SUM(C37:C50) -> 41767745
B37: Dešťová kanalizace – areál PR01 - západ (SO 1250.10) | C37: 38921.64
B38: Dešťová kanalizace - areál PR 01 - jih (SO 1250.11) | C38: 594717.65
B39: Dešťová kanalizace - AN PR 01 - jih (SO 1250.12) | C39: 1856445
B40: Dešťová kanalizace - vsak PR 01 - JIH (SO 1250.13) | C40: 6155405.1
B41: Dešťová kanalizace - areál PR 02 (SO 1250.20) | C41: 2356278.8
B42: Dešťová kanalizace - AN PR 02 (SO 1250.21) | C42: 2308368.5
B43: Dešťová kanalizace - RN PR 02 (SO 1250.22) | C43: 5042245.7
B44: Dešťová kanalizace - ČS + výtlak PR 02 (SO 1250.23) | C44: 2191531.2
B45: Dešťová kanalizace - vsak PR 02 (SO 1250.24) | C45: 7606231.3
...

Sheet Prefa konstrukce hal
L2: >> skryté sloupce << | AT2: {82a7035e-46a0-4833-af62-0bfe3c1c4662}
AT3: 2
D4: KRYCÍ LIST SOUPISU PRACÍ | M4: v --- níže se nacházejí doplnkové a pomocné údaje k sestavám --- v | AT4: False
D6: Stavba:
E7: RC Zone Přerov - Prefa konstrukce
D8: Objekt:
E9: 03 - Prefa konstrukce hala 01, 02, 03
D11: KSO: | I11: CC-CZ:
D12: Místo: | I12: Datum:
D14: Zadavatel: | I14: IČ:
I15: DIČ:
D17: Zhotovitel: | I17: IČ:
I18: DIČ:
D20: Projektant: | I20: IČ:
I21: DIČ:
D23: Zpracovatel: | I23: IČ:
I24: DIČ:
D26: Poznámka:
D30: Cena bez DPH | J30: =ROUND(J119, 2) -> 88315097
F32: Základ daně | I32: Sazba daně | J32: Výše daně
D33: DPH | E33: základní | F33: =ROUND((SUM(BE119:BE147)), 2) -> 88315097 | I33: 0.21 | J33: =ROUND(((SUM(BE119:BE147))*I33), 2) -> 18546170
E34: snížená | F34: =ROUND((SUM(BF119:BF147)), 2) -> 0 | I34: 0.12 | J34: =ROUND(((SUM(BF119:BF147))*I34), 2) -> 0
E35: zákl. přenesená | F35: =ROUND((SUM(BG119:BG147)), 2) -> 0 | I35: 0.21 | J35: =0 -> 0
E36: sníž. přenesená | F36: =ROUND((SUM(BH119:BH147)), 2) -> 0 | I36: 0.12 | J36: =0 -> 0
E37: nulová | F37: =ROUND((SUM(BI119:BI147)), 2) -> 0 | I37: 0 | J37: =0 -> 0
D39: Cena s DPH | G39: v | H39: CZK | J39: =SUM(J30:J37) -> 1.0686127e+08
D50: Projektant | G50: Zpracovatel
D61: Datum a podpis: | F61: Razítko | G61: Datum a podpis: | J61: Razítko
D65: Objednavatel | G65: Zhotovitel
D76: Datum a podpis: | F76: Razítko | G76: Datum a podpis: | J76: Razítko
C82: REKAPITULACE ČLENĚNÍ SOUPISU PRACÍ
C84: Stavba:
E85: =E7 -> RC Zone Přerov - Prefa konstrukce
C86: Objekt:
E87: =E9 -> 03 - Prefa konstrukce hala 01, 02, 03
C89: Místo: | F89: =F12 | I89: Datum: | J89: =IF(J12="","",J12)
C91: Zadavatel: | F91: =E15 | I91: Projektant: | J91: =E21
C92: Zhotovitel: | F92: =IF(E18="","",E18) | I92: Zpracovatel: | J92: =E24
C94: Kód dílu - Popis | J94: Cena celkem [CZK]
C96: Náklady ze soupisu prací | J96: =J119 -> 88315097 | AU96: -1
...
