Workbook
Name CisloRozpoctu: '[1]Krycí list'!$C$2
Name cislostavby: '[1]Krycí list'!$A$7
Name NazevRozpoctu: '[1]Krycí list'!$D$2
Name nazevstavby: '[1]Krycí list'!$C$7
Name SazbaDPH1: '[1]Krycí list'!$C$30
Name SazbaDPH2: '[1]Krycí list'!$C$32
Name SloupecMnozstvi: #REF!
Name Mena: Stavba!$J$29
Name Zaokrouhleni: Stavba!$G$27
Name ZakladDPHSniVypocet: Stavba!$F$78
Name CenaCelkemBezDPH: Stavba!$G$28
Name IČO: Stavba!$I$11
Name Vypracoval: Stavba!$D$14
Name SloupecMJ: #REF!
Name SloupecCC: #REF!
Name Projektant: Stavba!$D$8
Name CisloStavby: Stavba!$D$2
Name nazevobjektu: Stavba!$E$3
Name pdic: Stavba!$I$9
Name omisto: Stavba!$E$7
Name ZaZhotovitele: Stavba!$D$34
Name ZaObjednatele: Stavba!$G$34
Name ZakladDPHZakl: Stavba!$G$25
Name SloupecJC: #REF!
Name CenaCelkemVypocet: Stavba!$I$78
Name onazev: Stavba!$D$6
Name SloupecCisloPol: #REF!
Name padresa: Stavba!$D$9
Name PoptavkaID: Stavba!$A$1
Name opsc: Stavba!$D$7
Name Objednatel: Stavba!$D$5
Name MistoStavby: Stavba!$D$4
Name pPSC: Stavba!$D$10
Name SloupecPC: #REF!
Name Zhotovitel: Stavba!$D$11:$G$11
Name NazevStavby: Stavba!$E$2
Name CelkemDPHVypocet: Stavba!$H$78
Name SazbaDPH2: Stavba!$E$25
Name Print_Area: Stavba!$A$1:$J$110
Name DPHZakl: Stavba!$G$26
Name CisloStavebnihoRozpoctu: Stavba!$D$4
Name PocetMJ: #REF!
Name SazbaDPH1: Stavba!$E$23
Name NazevStavebnihoRozpoctu: Stavba!$E$4
Name DIČ: Stavba!$I$12
Name dmisto: Stavba!$E$13:$G$13
Name ZakladDPHZaklVypocet: Stavba!$G$78
Name Objekt: Stavba!$B$38
Name Z_B7E7C763_C459_487D_8ABA_5CFDDFBD5A84_.wvu.PrintArea: Stavba!$B$1:$J$36
Name dpsc: Stavba!$D$13
Name oico: Stavba!$I$5
Name cisloobjektu: Stavba!$D$3
Name oadresa: Stavba!$D$6
Name DPHSni: Stavba!$G$24
Name pmisto: Stavba!$E$10
Name CenaCelkem: Stavba!$G$29
Name odic: Stavba!$I$6
Name dadresa: Stavba!$D$12:$G$12
Name SloupecNazPol: #REF!
Name pico: Stavba!$I$8

Sheet Stavba
A1: #RTSROZP# | B1: Položkový rozpočet stavby
B2: Stavba: | D2: 2409.2 | E2: Český technologický park Brno, zóna C - objekty D, E, F - infrastruktura
B5: Objednatel: | D5: Technologický Park Brno, a.s. | H5: IČO: | I5: 48532215
D6: Purkyňova 646/107 | H6: DIČ: | I6: CZ48532215
D7: 61200 | E7: Brno-Medlánky
B8: Projektant: | H8: IČO:
H9: DIČ:
B11: Zhotovitel: | D11: STAVOS Brno, a.s. | H11: IČO: | I11: 652 77 911
D12: U Svitavy 1077/2 | H12: DIČ: | I12: CZ65277911
D13: 618 00 | E13: Brno
B14: Vypracoval:
B15: Rozpis ceny | I15: Celkem
A16: HSV | B16: HSV | I16: =SUMIF(F85:F109,A16,I85:I109)+SUMIF(F85:F109,"PSU",I85:I109) -> 30003372
A17: PSV | B17: PSV | I17: =SUMIF(F85:F109,A17,I85:I109) -> 169520
A18: MON | B18: MON | I18: =SUMIF(F85:F109,A18,I85:I109) -> 6591457
A19: VN | B19: Vedlejší náklady | I19: =SUMIF(F85:F109,A19,I85:I109) -> 305766
A20: ON | B20: Ostatní náklady | I20: =SUMIF(F85:F109,A20,I85:I109) -> 262937
B21: Celkem | I21: =SUM(I16:J20) -> 37333052
B22: Rekapitulace daní
A23: =ZakladDPHSni*Stavba!SazbaDPH1/100 -> 0 | B23: Základ pro sníženou DPH | E23: 15 | F23: % | G23: =Stavba!ZakladDPHSniVypocet -> 0 | J23: =Mena -> CZK
A24: =(A23-INT(A23))*100 -> 0 | B24: Snížená DPH | E24: =Stavba!SazbaDPH1 -> 15 | F24: % | G24: =A23 -> 0 | J24: =Mena -> CZK
A25: =ZakladDPHZakl*Stavba!SazbaDPH2/100 -> 7839941 | B25: Základ pro základní DPH | E25: 21 | F25: % | G25: =Stavba!ZakladDPHZaklVypocet -> 37333052 | J25: =Mena -> CZK
A26: =(A25-INT(A25))*100 -> 97.67 | B26: Základní DPH | E26: =Stavba!SazbaDPH2 -> 21 | F26: % | G26: =A25 -> 7839941 | J26: =Mena -> CZK
A27: =ZakladDPHSni+DPHSni+ZakladDPHZakl+DPHZakl -> 45172993 | B27: Zaokrouhlení | G27: =CenaCelkem-(ZakladDPHSni+DPHSni+ZakladDPHZakl+DPHZakl) -> 0 | J27: =Mena -> CZK
B28: Cena celkem bez DPH | G28: =Stavba!ZakladDPHSniVypocet+Stavba!ZakladDPHZaklVypocet -> 37333052 | J28: =Mena -> CZK
A29: =(A27-INT(A27))*100 -> 24.67 | B29: Cena celkem s DPH | G29: =A27 -> 45172993 | J29: CZK
C32: v | F32: dne
D35: Za zhotovitele | H35: Za objednatele
B37: Rekapitulace dílčích částí
A38: #CASTI>> | B38: Číslo | C38: Název | F38: =B23 -> Základ pro sníženou DPH | G38: =B25 -> Základ pro základní DPH | H38: DPH celkem | I38: Cena celkem | J38: %
A39: 1 | B39: Stavba | F39: ='00 000 Naklady'!AE29+'IO 710 IO 710 Pol'!AE356+'IO 720a IO 720a Pol'!AE149+'IO 730 IO 730 Pol'!AE113+'IO 730a IO 730a Pol'!AE124+'IO 754a IO 754a Pol'!AE68+'IO 760b IO 760b Pol'!AE29+'IO 763 IO 763 Pol'!AE46+'SO 000 SO 000 Pol'!AE129+'SO 600 SO 600 Pol'!AE116+'SO 601 SO 601 Pol'!AE123+'SO 602 SO 602 Pol'!AE120+'SO 603 SO 603 Pol'!AE160+'SO 603a SO 603a Pol'!AE101+'SO 606 SO 606 Pol'!AE561+'SO 606a SO 606a Pol'!AE215+'SO 630 SO 630 Pol'!AE82+'SO 640 SO 640 Pol'!AE38+'SO 641 SO 641 Pol'!AE41 -> 0 | G39: ='00 000 Naklady'!AF29+'IO 710 IO 710 Pol'!AF356+'IO 720a IO 720a Pol'!AF149+'IO 730 IO 730 Pol'!AF113+'IO 730a IO 730a Pol'!AF124+'IO 754a IO 754a Pol'!AF68+'IO 760b IO 760b Pol'!AF29+'IO 763 IO 763 Pol'!AF46+'SO 000 SO 000 Pol'!AF129+'SO 600 SO 600 Pol'!AF116+'SO 601 SO 601 Pol'!AF123+'SO 602 SO 602 Pol'!AF120+'SO 603 SO 603 Pol'!AF160+'SO 603a SO 603a Pol'!AF101+'SO 606 SO 606 Pol'!AF561+'SO 606a SO 606a Pol'!AF215+'SO 630 SO 630 Pol'!AF82+'SO 640 SO 640 Pol'!AF38+'SO 641 SO 641 Pol'!AF41 -> 37333052 | H39: =(F39*Stavba!SazbaDPH1/100)+(G39*Stavba!SazbaDPH2/100) -> 7839941 | I39: =F39+G39+H39 -> 45172993 | J39: =IF(Stavba!CenaCelkemVypocet=0,"",I39/Stavba!CenaCelkemVypocet*100) -> 100
A40: 2 | B40: 00 | C40: Vedlejší a ostatní náklady | F40: ='00 000 Naklady'!AE29 -> 0 | G40: ='00 000 Naklady'!AF29 -> 568703 | H40: =(F40*Stavba!SazbaDPH1/100)+(G40*Stavba!SazbaDPH2/100) -> 119427.63 | I40: =F40+G40+H40 -> 688130.63 | J40: =IF(Stavba!CenaCelkemVypocet=0,"",I40/Stavba!CenaCelkemVypocet*100) -> 1.5233231
A41: 3 | B41: 000 | C41: Vedlejší a ostatní náklady | F41: ='00 000 Naklady'!AE29 -> 0 | G41: ='00 000 Naklady'!AF29 -> 568703 | H41: =(F41*Stavba!SazbaDPH1/100)+(G41*Stavba!SazbaDPH2/100) -> 119427.63 | I41: =F41+G41+H41 -> 688130.63 | J41: =IF(Stavba!CenaCelkemVypocet=0,"",I41/Stavba!CenaCelkemVypocet*100) -> 1.5233231
A42: 2 | B42: IO 710 | C42: Plynovod - přeložka | F42: ='IO 710 IO 710 Pol'!AE356 -> 0 | G42: ='IO 710 IO 710 Pol'!AF356 -> 5016734.5 | H42: =(F42*Stavba!SazbaDPH1/100)+(G42*Stavba!SazbaDPH2/100) -> 1053514.3 | I42: =F42+G42+H42 -> 6070248.8 | J42: =IF(Stavba!CenaCelkemVypocet=0,"",I42/Stavba!CenaCelkemVypocet*100) -> 13.437783
A43: 3 | B43: IO 710 | C43: Plynovod - přeložka | F43: ='IO 710 IO 710 Pol'!AE356 -> 0 | G43: ='IO 710 IO 710 Pol'!AF356 -> 5016734.5 | H43: =(F43*Stavba!SazbaDPH1/100)+(G43*Stavba!SazbaDPH2/100) -> 1053514.3 | I43: =F43+G43+H43 -> 6070248.8 | J43: =IF(Stavba!CenaCelkemVypocet=0,"",I43/Stavba!CenaCelkemVypocet*100) -> 13.437783
A44: 2 | B44: IO 720a | C44: Přípojka kanalizace (objekt D) | F44: ='IO 720a IO 720a Pol'!AE149 -> 0 | G44: ='IO 720a IO 720a Pol'!AF149 -> 110566.6 | H44: =(F44*Stavba!SazbaDPH1/100)+(G44*Stavba!SazbaDPH2/100) -> 23218.986 | I44: =F44+G44+H44 -> 133785.59 | J44: =IF(Stavba!CenaCelkemVypocet=0,"",I44/Stavba!CenaCelkemVypocet*100) -> 0.29616277
A45: 3 | B45: IO 720a | C45: Přípojka kanalizace (objekt D) | F45: ='IO 720a IO 720a Pol'!AE149 -> 0 | G45: ='IO 720a IO 720a Pol'!AF149 -> 110566.6 | H45: =(F45*Stavba!SazbaDPH1/100)+(G45*Stavba!SazbaDPH2/100) -> 23218.986 | I45: =F45+G45+H45 -> 133785.59 | J45: =IF(Stavba!CenaCelkemVypocet=0,"",I45/Stavba!CenaCelkemVypocet*100) -> 0.29616277
A46: 2 | B46: IO 730 | C46: Vodovod - řady | F46: ='IO 730 IO 730 Pol'!AE113 -> 0 | G46: ='IO 730 IO 730 Pol'!AF113 -> 484680.99 | H46: =(F46*Stavba!SazbaDPH1/100)+(G46*Stavba!SazbaDPH2/100) -> 101783.01 | I46: =F46+G46+H46 -> 586464 | J46: =IF(Stavba!CenaCelkemVypocet=0,"",I46/Stavba!CenaCelkemVypocet*100) -> 1.2982624
A47: 3 | B47: IO 730 | C47: Vodovod - řady | F47: ='IO 730 IO 730 Pol'!AE113 -> 0 | G47: ='IO 730 IO 730 Pol'!AF113 -> 484680.99 | H47: =(F47*Stavba!SazbaDPH1/100)+(G47*Stavba!SazbaDPH2/100) -> 101783.01 | I47: =F47+G47+H47 -> 586464 | J47: =IF(Stavba!CenaCelkemVypocet=0,"",I47/Stavba!CenaCelkemVypocet*100) -> 1.2982624
A48: 2 | B48: IO 730a | C48: Vodovod - přípojka D | F48: ='IO 730a IO 730a Pol'!AE124 -> 0 | G48: ='IO 730a IO 730a Pol'!AF124 -> 233593.41 | H48: =(F48*Stavba!SazbaDPH1/100)+(G48*Stavba!SazbaDPH2/100) -> 49054.616 | I48: =F48+G48+H48 -> 282648.03 | J48: =IF(Stavba!CenaCelkemVypocet=0,"",I48/Stavba!CenaCelkemVypocet*100) -> 0.62570134
...

Sheet VzorPolozky
A1: Položkový rozpočet
A2: S:
A3: O:
A4: R:

Sheet 00 000 Naklady
A1: Položkový rozpočet | AG1: #TypZaznamu#
A2: S: | B2: 2409.2 | C2: Český technologický park Brno, zóna C - objekty D, E, F - infrastruktura | AG2: STA
A3: O: | B3: 00 | C3: Vedlejší a ostatní náklady | AC3: NAK | AG3: OBJ
A4: R: | B4: 000 | C4: Vedlejší a ostatní náklady | AG4: ROZ
A6: P.č. | B6: Číslo položky | C6: Název položky | D6: MJ | E6: Množství | F6: Cena / MJ | G6: Celkem | H6: Dodávka | I6: Dodávka celk. | J6: Montáž | K6: Montáž celk. | L6: DPH | M6: Cena s DPH | N6: Hmotnost / MJ | O6: Hmotnost celk.(t) | P6: Dem. hmotnost / MJ | Q6: Dem. hmotnost celk.(t) | R6: Ceník | S6: Cen. soustava / platnost | T6: Cenová úroveň | U6: Nhod / MJ | V6: Nhod celk. | W6: Dodavatel | X6: Typ položky
A8: Díl: | B8: VN | C8: Vedlejší náklady | G8: =SUMIF(AG9:AG17,"<>NOR",G9:G17) -> 305766 | I8: =SUM(I9:I17) -> 0 | K8: =SUM(K9:K17) -> 0 | M8: =SUM(M9:M17) -> 369976.86 | O8: =SUM(O9:O17) -> 0 | Q8: =SUM(Q9:Q17) -> 0 | V8: =SUM(V9:V17) -> 0 | AG8: DIL
A9: 1 | B9: 0007T | C9: Zkoušky únosnosti pláně | D9: Soubor | E9: 1 | F9: 57148 | G9: =ROUND(E9*F9,2) -> 57148 | I9: =ROUND(E9*H9,2) -> 0 | K9: =ROUND(E9*J9,2) -> 0 | L9: 21 | M9: =G9*(1+L9/100) -> 69149.08 | N9: 0 | O9: =ROUND(E9*N9,2) -> 0 | P9: 0 | Q9: =ROUND(E9*P9,2) -> 0 | S9: Vlastní | T9: Indiv | U9: 0 | V9: =ROUND(E9*U9,2) -> 0 | X9: VRN | AG9: POL99_0
A10: 2 | B10: 005111020R | C10: Vytyčení stavby | D10: Soubor | E10: 1 | F10: 41108 | G10: =ROUND(E10*F10,2) -> 41108 | I10: =ROUND(E10*H10,2) -> 0 | K10: =ROUND(E10*J10,2) -> 0 | L10: 21 | M10: =G10*(1+L10/100) -> 49740.68 | N10: 0 | O10: =ROUND(E10*N10,2) -> 0 | P10: 0 | Q10: =ROUND(E10*P10,2) -> 0 | S10: RTS 19/ II | T10: Indiv | U10: 0 | V10: =ROUND(E10*U10,2) -> 0 | X10: VRN | AG10: POL99_2
A11: 3 | B11: 005111021R | C11: Vytyčení inženýrských sítí | D11: Soubor | E11: 1 | F11: 32235 | G11: =ROUND(E11*F11,2) -> 32235 | I11: =ROUND(E11*H11,2) -> 0 | K11: =ROUND(E11*J11,2) -> 0 | L11: 21 | M11: =G11*(1+L11/100) -> 39004.35 | N11: 0 | O11: =ROUND(E11*N11,2) -> 0 | P11: 0 | Q11: =ROUND(E11*P11,2) -> 0 | S11: RTS 19/ II | T11: Indiv | U11: 0 | V11: =ROUND(E11*U11,2) -> 0 | X11: VRN | AG11: POL99_2
A12: 4 | B12: 00511T | C12: Geodetické zaměření stavby | D12: Soubor | E12: 1 | F12: 5458 | G12: =ROUND(E12*F12,2) -> 5458 | I12: =ROUND(E12*H12,2) -> 0 | K12: =ROUND(E12*J12,2) -> 0 | L12: 21 | M12: =G12*(1+L12/100) -> 6604.18 | N12: 0 | O12: =ROUND(E12*N12,2) -> 0 | P12: 0 | Q12: =ROUND(E12*P12,2) -> 0 | S12: Vlastní | T12: Indiv | U12: 0 | V12: =ROUND(E12*U12,2) -> 0 | X12: VRN | AG12: POL99_0
A13: 5 | B13: 005127 RT | C13: Pronájem mobilního WC po dobu výstavby vč.dopravy | D13: Soubor | E13: 1 | F13: 16301 | G13: =ROUND(E13*F13,2) -> 16301 | I13: =ROUND(E13*H13,2) -> 0 | K13: =ROUND(E13*J13,2) -> 0 | L13: 21 | M13: =G13*(1+L13/100) -> 19724.21 | N13: 0 | O13: =ROUND(E13*N13,2) -> 0 | P13: 0 | Q13: =ROUND(E13*P13,2) -> 0 | S13: Vlastní | T13: Indiv | U13: 0 | V13: =ROUND(E13*U13,2) -> 0 | X13: VRN | AG13: POL99_0
A14: 6 | B14: 005121010R | C14: Vybudování zařízení staveniště | D14: Soubor | E14: 1 | F14: 30346 | G14: =ROUND(E14*F14,2) -> 30346 | I14: =ROUND(E14*H14,2) -> 0 | K14: =ROUND(E14*J14,2) -> 0 | L14: 21 | M14: =G14*(1+L14/100) -> 36718.66 | N14: 0 | O14: =ROUND(E14*N14,2) -> 0 | P14: 0 | Q14: =ROUND(E14*P14,2) -> 0 | S14: RTS 19/ II | T14: Indiv | U14: 0 | V14: =ROUND(E14*U14,2) -> 0 | X14: VRN | AG14: POL99_2
A15: 7 | B15: 005121020R | C15: Provoz zařízení staveniště | D15: Soubor | E15: 1 | F15: 21037 | G15: =ROUND(E15*F15,2) -> 21037 | I15: =ROUND(E15*H15,2) -> 0 | K15: =ROUND(E15*J15,2) -> 0 | L15: 21 | M15: =G15*(1+L15/100) -> 25454.77 | N15: 0 | O15: =ROUND(E15*N15,2) -> 0 | P15: 0 | Q15: =ROUND(E15*P15,2) -> 0 | S15: RTS 19/ II | T15: Indiv | U15: 0 | V15: =ROUND(E15*U15,2) -> 0 | X15: VRN | AG15: POL99_2
A16: 8 | B16: 005121030R | C16: Odstranění zařízení staveniště | D16: Soubor | E16: 1 | F16: 83981 | G16: =ROUND(E16*F16,2) -> 83981 | I16: =ROUND(E16*H16,2) -> 0 | K16: =ROUND(E16*J16,2) -> 0 | L16: 21 | M16: =G16*(1+L16/100) -> 101617.01 | N16: 0 | O16: =ROUND(E16*N16,2) -> 0 | P16: 0 | Q16: =ROUND(E16*P16,2) -> 0 | S16: RTS 19/ II | T16: Indiv | U16: 0 | V16: =ROUND(E16*U16,2) -> 0 | X16: VRN | AG16: POL99_2
A17: 9 | B17: 005124010R | C17: Koordinační činnost | D17: Soubor | E17: 1 | F17: 18152 | G17: =ROUND(E17*F17,2) -> 18152 | I17: =ROUND(E17*H17,2) -> 0 | K17: =ROUND(E17*J17,2) -> 0 | L17: 21 | M17: =G17*(1+L17/100) -> 21963.92 | N17: 0 | O17: =ROUND(E17*N17,2) -> 0 | P17: 0 | Q17: =ROUND(E17*P17,2) -> 0 | S17: RTS 19/ II | T17: Indiv | U17: 0 | V17: =ROUND(E17*U17,2) -> 0 | X17: VRN | AG17: POL99_2
A18: Díl: | B18: ON | C18: Ostatní náklady | G18: =SUMIF(AG19:AG27,"<>NOR",G19:G27) -> 262937 | I18: =SUM(I19:I27) -> 0 | K18: =SUM(K19:K27) -> 0 | M18: =SUM(M19:M27) -> 318153.77 | O18: =SUM(O19:O27) -> 0 | Q18: =SUM(Q19:Q27) -> 0 | V18: =SUM(V19:V27) -> 0 | AG18: DIL
A19: 10 | B19: 00896T | C19: Oplocení staveniště po celou dobu výstavby | D19: Soubor | E19: 1 | F19: 18975 | G19: =ROUND(E19*F19,2) -> 18975 | I19: =ROUND(E19*H19,2) -> 0 | K19: =ROUND(E19*J19,2) -> 0 | L19: 21 | M19: =G19*(1+L19/100) -> 22959.75 | N19: 0 | O19: =ROUND(E19*N19,2) -> 0 | P19: 0 | Q19: =ROUND(E19*P19,2) -> 0 | S19: Vlastní | T19: Indiv | U19: 0 | V19: =ROUND(E19*U19,2) -> 0 | X19: VRN | AG19: POL99_0
A20: 11 | B20: 004111010R | C20: Průzkumné práce | D20: Soubor | E20: 1 | F20: 6277 | G20: =ROUND(E20*F20,2) -> 6277 | I20: =ROUND(E20*H20,2) -> 0 | K20: =ROUND(E20*J20,2) -> 0 | L20: 21 | M20: =G20*(1+L20/100) -> 7595.17 | N20: 0 | O20: =ROUND(E20*N20,2) -> 0 | P20: 0 | Q20: =ROUND(E20*P20,2) -> 0 | S20: RTS 19/ II | T20: Indiv | U20: 0 | V20: =ROUND(E20*U20,2) -> 0 | X20: VRN | AG20: POL99_2
A21: 12 | B21: 00511 R | C21: Geodetické práce | D21: Soubor | E21: 1 | F21: 47966 | G21: =ROUND(E21*F21,2) -> 47966 | I21: =ROUND(E21*H21,2) -> 0 | K21: =ROUND(E21*J21,2) -> 0 | L21: 21 | M21: =G21*(1+L21/100) -> 58038.86 | N21: 0 | O21: =ROUND(E21*N21,2) -> 0 | P21: 0 | Q21: =ROUND(E21*P21,2) -> 0 | S21: RTS 19/ II | T21: Indiv | U21: 0 | V21: =ROUND(E21*U21,2) -> 0 | X21: VRN | AG21: POL99_2
A22: 13 | B22: 005211020R | C22: Ochrana stávaj. inženýrských sítí na staveništi | D22: Soubor | E22: 1 | F22: 21480 | G22: =ROUND(E22*F22,2) -> 21480 | I22: =ROUND(E22*H22,2) -> 0 | K22: =ROUND(E22*J22,2) -> 0 | L22: 21 | M22: =G22*(1+L22/100) -> 25990.8 | N22: 0 | O22: =ROUND(E22*N22,2) -> 0 | P22: 0 | Q22: =ROUND(E22*P22,2) -> 0 | S22: RTS 19/ II | T22: Indiv | U22: 0 | V22: =ROUND(E22*U22,2) -> 0 | X22: VRN | AG22: POL99_2
A23: 14 | B23: 005211080R | C23: Bezpečnostní a hygienická opatření na staveništi | D23: Soubor | E23: 1 | F23: 38685 | G23: =ROUND(E23*F23,2) -> 38685 | I23: =ROUND(E23*H23,2) -> 0 | K23: =ROUND(E23*J23,2) -> 0 | L23: 21 | M23: =G23*(1+L23/100) -> 46808.85 | N23: 0 | O23: =ROUND(E23*N23,2) -> 0 | P23: 0 | Q23: =ROUND(E23*P23,2) -> 0 | S23: RTS 19/ II | T23: Indiv | U23: 0 | V23: =ROUND(E23*U23,2) -> 0 | X23: VRN | AG23: POL99_2
A24: 15 | B24: 00523 R | C24: Zkoušky a revize | D24: Soubor | E24: 1 | F24: 58326 | G24: =ROUND(E24*F24,2) -> 58326 | I24: =ROUND(E24*H24,2) -> 0 | K24: =ROUND(E24*J24,2) -> 0 | L24: 21 | M24: =G24*(1+L24/100) -> 70574.46 | N24: 0 | O24: =ROUND(E24*N24,2) -> 0 | P24: 0 | Q24: =ROUND(E24*P24,2) -> 0 | S24: RTS 19/ II | T24: Indiv | U24: 0 | V24: =ROUND(E24*U24,2) -> 0 | X24: VRN | AG24: POL99_2
A25: 16 | B25: 005241010R | C25: Dokumentace skutečného provedení | D25: Soubor | E25: 1 | F25: 37932 | G25: =ROUND(E25*F25,2) -> 37932 | I25: =ROUND(E25*H25,2) -> 0 | K25: =ROUND(E25*J25,2) -> 0 | L25: 21 | M25: =G25*(1+L25/100) -> 45897.72 | N25: 0 | O25: =ROUND(E25*N25,2) -> 0 | P25: 0 | Q25: =ROUND(E25*P25,2) -> 0 | S25: RTS 19/ II | T25: Indiv | U25: 0 | V25: =ROUND(E25*U25,2) -> 0 | X25: VRN | AG25: POL99_2
A26: 17 | B26: 005241020R | C26: Geodetické zaměření skutečného provedení | D26: Soubor | E26: 1 | F26: 16995 | G26: =ROUND(E26*F26,2) -> 16995 | I26: =ROUND(E26*H26,2) -> 0 | K26: =ROUND(E26*J26,2) -> 0 | L26: 21 | M26: =G26*(1+L26/100) -> 20563.95 | N26: 0 | O26: =ROUND(E26*N26,2) -> 0 | P26: 0 | Q26: =ROUND(E26*P26,2) -> 0 | S26: RTS 19/ II | T26: Indiv | U26: 0 | V26: =ROUND(E26*U26,2) -> 0 | X26: VRN | AG26: POL99_2
A27: 18 | B27: 005241030T | C27: Vyhotovení geometrického plánu | D27: Soubor | E27: 1 | F27: 16301 | G27: =ROUND(E27*F27,2) -> 16301 | I27: =ROUND(E27*H27,2) -> 0 | K27: =ROUND(E27*J27,2) -> 0 | L27: 21 | M27: =G27*(1+L27/100) -> 19724.21 | N27: 0 | O27: =ROUND(E27*N27,2) -> 0 | P27: 0 | Q27: =ROUND(E27*P27,2) -> 0 | S27: Vlastní | T27: Indiv | U27: 0 | V27: =ROUND(E27*U27,2) -> 0 | X27: VRN | AG27: POL99_0
AE28: 15 | AF28: 21 | AG28: DPH
B29: Celkem | G29: =G8+G18 -> 568703 | AE29: =SUMIF(L7:L27,AE28,G7:G27) -> 0 | AF29: =SUMIF(L7:L27,AF28,G7:G27) -> 568703 | AG29: SUM
A32: Poznámky uchazeče k zadání
AG33: POPUZIV
AG39: END

Sheet IO 710 IO 710 Pol
A1: Položkový rozpočet | AG1: #TypZaznamu#
A2: S: | B2: 2409.2 | C2: Český technologický park Brno, zóna C - objekty D, E, F - infrastruktura | AG2: STA
A3: O: | B3: IO 710 | C3: Plynovod - přeložka | AC3: STA | AG3: OBJ
A4: R: | B4: IO 710 | C4: Plynovod - přeložka | AG4: ROZ
A6: P.č. | B6: Číslo položky | C6: Název položky | D6: MJ | E6: Množství | F6: Cena / MJ | G6: Celkem | H6: Dodávka | I6: Dodávka celk. | J6: Montáž | K6: Montáž celk. | L6: DPH | M6: Cena s DPH | N6: Hmotnost / MJ | O6: Hmotnost celk.(t) | P6: Dem. hmotnost / MJ | Q6: Dem. hmotnost celk.(t) | R6: Ceník | S6: Cen. soustava / platnost | T6: Cenová úroveň | U6: Nhod / MJ | V6: Nhod celk. | W6: Dodavatel | X6: Typ položky
A8: Díl: | B8: 1 | C8: Zemní práce | G8: =SUMIF(AG9:AG156,"<>NOR",G9:G156) -> 1713227.1 | I8: =SUM(I9:I156) -> 0 | K8: =SUM(K9:K156) -> 0 | M8: =SUM(M9:M156) -> 2073004.8 | O8: =SUM(O9:O156) -> 492.54 | Q8: =SUM(Q9:Q156) -> 17.02 | V8: =SUM(V9:V156) -> 4846.74 | AG8: DIL
A9: 1 | B9: 113107540R00 | C9: Odstranění podkladu pl. 50 m2,kam.drcené tl.40 cm | D9: m2 | E9: 11.25 | F9: 153 | G9: =ROUND(E9*F9,2) -> 1721.25 | I9: =ROUND(E9*H9,2) -> 0 | K9: =ROUND(E9*J9,2) -> 0 | L9: 21 | M9: =G9*(1+L9/100) -> 2082.7125 | N9: 0 | O9: =ROUND(E9*N9,2) -> 0 | P9: 0.88 | Q9: =ROUND(E9*P9,2) -> 9.9 | S9: RTS 19/ II | T9: RTS 19/ II | U9: 1.248 | V9: =ROUND(E9*U9,2) -> 14.04 | X9: Práce | AG9: POL1_1
C10: asfaltová komunikace : | AG10: VV | AH10: 0
C11: 7,50*1,50 | E11: 11.25 | AG11: VV | AH11: 0
A12: 2 | B12: 113108310R00 | C12: Odstranění asfaltové vrstvy pl. do 50 m2, tl.10 cm | D12: m2 | E12: 11.25 | F12: 228.5 | G12: =ROUND(E12*F12,2) -> 2570.63 | I12: =ROUND(E12*H12,2) -> 0 | K12: =ROUND(E12*J12,2) -> 0 | L12: 21 | M12: =G12*(1+L12/100) -> 3110.4623 | N12: 0 | O12: =ROUND(E12*N12,2) -> 0 | P12: 0.22 | Q12: =ROUND(E12*P12,2) -> 2.48 | S12: RTS 19/ II | T12: RTS 19/ II | U12: 0.375 | V12: =ROUND(E12*U12,2) -> 4.22 | X12: Práce | AG12: POL1_1
C13: asfaltová komunikace : | AG13: VV | AH13: 0
C14: 7,50*1,50 | E14: 11.25 | AG14: VV | AH14: 0
A15: 3 | B15: 132201219R00 | C15: Přípl.za lepivost,hloubení rýh 200cm,hor.3,STROJNĚ | D15: m3 | E15: 539.9625 | F15: 39.6 | G15: =ROUND(E15*F15,2) -> 21382.52 | I15: =ROUND(E15*H15,2) -> 0 | K15: =ROUND(E15*J15,2) -> 0 | L15: 21 | M15: =G15*(1+L15/100) -> 25872.849 | N15: 0 | O15: =ROUND(E15*N15,2) -> 0 | P15: 0 | Q15: =ROUND(E15*P15,2) -> 0 | S15: RTS 19/ II | T15: RTS 19/ II | U15: 0.084 | V15: =ROUND(E15*U15,2) -> 45.36 | X15: Práce | AG15: POL1_1
C16: přeložka plynu : | AG16: VV | AH16: 0
C17: Začátek provozního součtu | AG17: VV
C18: 392,70*1,10*2,50 | E18: 1079.925 | AG18: VV | AH18: 2
C19: Konec provozního součtu | AG19: VV
C20: 1079,9250/2 | E20: 539.9625 | AG20: VV | AH20: 0
A21: 4 | B21: 113106231R00 | C21: Rozebrání dlažeb ze zámkové dlažby v kamenivu | D21: m2 | E21: 6 | F21: 83 | G21: =ROUND(E21*F21,2) -> 498 | I21: =ROUND(E21*H21,2) -> 0 | K21: =ROUND(E21*J21,2) -> 0 | L21: 21 | M21: =G21*(1+L21/100) -> 602.58 | N21: 0 | O21: =ROUND(E21*N21,2) -> 0 | P21: 0.225 | Q21: =ROUND(E21*P21,2) -> 1.35 | S21: RTS 19/ II | T21: RTS 19/ II | U21: 0.142 | V21: =ROUND(E21*U21,2) -> 0.85 | X21: Práce | AG21: POL1_1
C22: stávající chodník : | AG22: VV | AH22: 0
C23: 1,50*2,00 | E23: 3 | AG23: VV | AH23: 0
C24: 1,50*2,00 | E24: 3 | AG24: VV | AH24: 0
A25: 5 | B25: 113151111R00 | C25: Rozebrání ploch ze silničních panelů | D25: m2 | E25: 6 | F25: 152 | G25: =ROUND(E25*F25,2) -> 912 | I25: =ROUND(E25*H25,2) -> 0 | K25: =ROUND(E25*J25,2) -> 0 | L25: 21 | M25: =G25*(1+L25/100) -> 1103.52 | N25: 0 | O25: =ROUND(E25*N25,2) -> 0 | P25: 0.355 | Q25: =ROUND(E25*P25,2) -> 2.13 | S25: RTS 19/ II | T25: RTS 19/ II | U25: 0.062 | V25: =ROUND(E25*U25,2) -> 0.37 | X25: Práce | AG25: POL1_1
C26: zachování průjezdnosti panelové cesty : | AG26: VV | AH26: 0
C27: odstranění panelů po zhotovení prací : | AG27: VV | AH27: 0
C28: 6,00 | E28: 6 | AG28: VV | AH28: 0
A29: 6 | B29: 113202111R00 | C29: Vytrhání obrub z krajníků nebo obrubníků stojatých | D29: m | E29: 8 | F29: 73 | G29: =ROUND(E29*F29,2) -> 584 | I29: =ROUND(E29*H29,2) -> 0 | K29: =ROUND(E29*J29,2) -> 0 | L29: 21 | M29: =G29*(1+L29/100) -> 706.64 | N29: 0 | O29: =ROUND(E29*N29,2) -> 0 | P29: 0.145 | Q29: =ROUND(E29*P29,2) -> 1.16 | S29: RTS 19/ II | T29: RTS 19/ II | U29: 0.133 | V29: =ROUND(E29*U29,2) -> 1.06 | X29: Práce | AG29: POL1_1
C30: stávající chodník : | AG30: VV | AH30: 0
C31: 2*2,00 | E31: 4 | AG31: VV | AH31: 0
C32: 2*2,00 | E32: 4 | AG32: VV | AH32: 0
A33: 7 | B33: 121101103R00 | C33: Sejmutí ornice s přemístěním přes 100 do 250 m | D33: m3 | E33: 1.2 | F33: 183.5 | G33: =ROUND(E33*F33,2) -> 220.2 | I33: =ROUND(E33*H33,2) -> 0 | K33: =ROUND(E33*J33,2) -> 0 | L33: 21 | M33: =G33*(1+L33/100) -> 266.442 | N33: 0 | O33: =ROUND(E33*N33,2) -> 0 | P33: 0 | Q33: =ROUND(E33*P33,2) -> 0 | S33: RTS 19/ II | T33: RTS 19/ II | U33: 0.0134 | V33: =ROUND(E33*U33,2) -> 0.02 | X33: Práce | AG33: POL1_1
C34: zachování průjezdnosti panelové cesty : | AG34: VV | AH34: 0
C35: sejmutí ornice : | AG35: VV | AH35: 0
C36: 6,00*0,20 | E36: 1.2 | AG36: VV | AH36: 0
A37: 8 | B37: 122201101R00 | C37: Odkopávky nezapažené v hor. 3 do 100 m3 | D37: m3 | E37: 1.2 | F37: 200.5 | G37: =ROUND(E37*F37,2) -> 240.6 | I37: =ROUND(E37*H37,2) -> 0 | K37: =ROUND(E37*J37,2) -> 0 | L37: 21 | M37: =G37*(1+L37/100) -> 291.126 | N37: 0 | O37: =ROUND(E37*N37,2) -> 0 | P37: 0 | Q37: =ROUND(E37*P37,2) -> 0 | S37: RTS 19/ II | T37: RTS 19/ II | U37: 0.368 | V37: =ROUND(E37*U37,2) -> 0.44 | X37: Práce | AG37: POL1_1
C38: zachování průjezdnosti panelové cesty : | AG38: VV | AH38: 0
C39: odkopávka pod ornicí : | AG39: VV | AH39: 0
C40: 6,00*0,20 | E40: 1.2 | AG40: VV | AH40: 0
A41: 9 | B41: 130001101R00 | C41: Příplatek za ztížené hloubení v blízkosti vedení | D41: m3 | E41: 90 | F41: 502.5 | G41: =ROUND(E41*F41,2) -> 45225 | I41: =ROUND(E41*H41,2) -> 0 | K41: =ROUND(E41*J41,2) -> 0 | L41: 21 | M41: =G41*(1+L41/100) -> 54722.25 | N41: 0 | O41: =ROUND(E41*N41,2) -> 0 | P41: 0 | Q41: =ROUND(E41*P41,2) -> 0 | S41: RTS 19/ II | T41: RTS 19/ II | U41: 1.763 | V41: =ROUND(E41*U41,2) -> 158.67 | X41: Práce | AG41: POL1_1
A42: 10 | B42: 132201211R00 | C42: Hloubení rýh š.do 200 cm hor.3 do 100 m3,STROJNĚ | D42: m3 | E42: 1719.3 | F42: 214.5 | G42: =ROUND(E42*F42,2) -> 368789.85 | I42: =ROUND(E42*H42,2) -> 0 | K42: =ROUND(E42*J42,2) -> 0 | L42: 21 | M42: =G42*(1+L42/100) -> 446235.72 | N42: 0 | O42: =ROUND(E42*N42,2) -> 0 | P42: 0 | Q42: =ROUND(E42*P42,2) -> 0 | S42: RTS 19/ II | T42: RTS 19/ II | U42: 0.222 | V42: =ROUND(E42*U42,2) -> 381.68 | X42: Práce | AG42: POL1_1
...

Sheet IO 720a IO 720a Pol
A1: Položkový rozpočet | AG1: #TypZaznamu#
A2: S: | B2: 2409.2 | C2: Český technologický park Brno, zóna C - objekty D, E, F - infrastruktura | AG2: STA
A3: O: | B3: IO 720a | C3: Přípojka kanalizace (objekt D) | AC3: STA | AG3: OBJ
A4: R: | B4: IO 720a | C4: Přípojka kanalizace (objekt D) | AG4: ROZ
A6: P.č. | B6: Číslo položky | C6: Název položky | D6: MJ | E6: Množství | F6: Cena / MJ | G6: Celkem | H6: Dodávka | I6: Dodávka celk. | J6: Montáž | K6: Montáž celk. | L6: DPH | M6: Cena s DPH | N6: Hmotnost / MJ | O6: Hmotnost celk.(t) | P6: Dem. hmotnost / MJ | Q6: Dem. hmotnost celk.(t) | R6: Ceník | S6: Cen. soustava / platnost | T6: Cenová úroveň | U6: Nhod / MJ | V6: Nhod celk. | W6: Dodavatel | X6: Typ položky
A8: Díl: | B8: 1 | C8: Zemní práce | G8: =SUMIF(AG9:AG47,"<>NOR",G9:G47) -> 26527.19 | I8: =SUM(I9:I47) -> 0 | K8: =SUM(K9:K47) -> 0 | M8: =SUM(M9:M47) -> 32097.9 | O8: =SUM(O9:O47) -> 0.05 | Q8: =SUM(Q9:Q47) -> 0 | V8: =SUM(V9:V47) -> 80.29 | AG8: DIL
A9: 1 | B9: 132201219R00 | C9: Přípl.za lepivost,hloubení rýh 200cm,hor.3,STROJNĚ | D9: m3 | E9: 16.2662 | F9: 39.6 | G9: =ROUND(E9*F9,2) -> 644.14 | I9: =ROUND(E9*H9,2) -> 0 | K9: =ROUND(E9*J9,2) -> 0 | L9: 21 | M9: =G9*(1+L9/100) -> 779.4094 | N9: 0 | O9: =ROUND(E9*N9,2) -> 0 | P9: 0 | Q9: =ROUND(E9*P9,2) -> 0 | S9: RTS 19/ II | T9: RTS 19/ II | U9: 0.084 | V9: =ROUND(E9*U9,2) -> 1.37 | X9: Práce | AG9: POL1_1
C10: rýha pro kanalizaci : | AG10: VV | AH10: 0
C11: Začátek provozního součtu | AG11: VV
C12: 8,45*1,10*3,50 | E12: 32.5325 | AG12: VV | AH12: 2
C13: Konec provozního součtu | AG13: VV
C14: 32,5325/2 | E14: 16.26625 | AG14: VV | AH14: 0
A15: 2 | B15: 132201211R00 | C15: Hloubení rýh š.do 200 cm hor.3 do 100 m3,STROJNĚ | D15: m3 | E15: 32.5325 | F15: 214.5 | G15: =ROUND(E15*F15,2) -> 6978.22 | I15: =ROUND(E15*H15,2) -> 0 | K15: =ROUND(E15*J15,2) -> 0 | L15: 21 | M15: =G15*(1+L15/100) -> 8443.6462 | N15: 0 | O15: =ROUND(E15*N15,2) -> 0 | P15: 0 | Q15: =ROUND(E15*P15,2) -> 0 | S15: RTS 19/ II | T15: RTS 19/ II | U15: 0.222 | V15: =ROUND(E15*U15,2) -> 7.22 | X15: Práce | AG15: POL1_1
C16: rýha pro kanalizaci : | AG16: VV | AH16: 0
C17: 8,45*1,10*3,50 | E17: 32.53 | AG17: VV | AH17: 0
A18: 3 | B18: 151101102R00 | C18: Pažení a rozepření stěn rýh - příložné - hl. do 4m | D18: m2 | E18: 59.15 | F18: 69.5 | G18: =ROUND(E18*F18,2) -> 4110.93 | I18: =ROUND(E18*H18,2) -> 0 | K18: =ROUND(E18*J18,2) -> 0 | L18: 21 | M18: =G18*(1+L18/100) -> 4974.2253 | N18: 0.00086 | O18: =ROUND(E18*N18,2) -> 0.05 | P18: 0 | Q18: =ROUND(E18*P18,2) -> 0 | S18: RTS 19/ II | T18: RTS 19/ II | U18: 0.479 | V18: =ROUND(E18*U18,2) -> 28.33 | X18: Práce | AG18: POL1_1
C19: rýha pro kanalizaci : | AG19: VV | AH19: 0
C20: (8,45*3,50)*2 | E20: 59.15 | AG20: VV | AH20: 0
A21: 4 | B21: 151101112R00 | C21: Odstranění pažení stěn rýh - příložné - hl. do 4 m | D21: m2 | E21: 59.15 | F21: 41.3 | G21: =ROUND(E21*F21,2) -> 2442.9 | I21: =ROUND(E21*H21,2) -> 0 | K21: =ROUND(E21*J21,2) -> 0 | L21: 21 | M21: =G21*(1+L21/100) -> 2955.909 | N21: 0 | O21: =ROUND(E21*N21,2) -> 0 | P21: 0 | Q21: =ROUND(E21*P21,2) -> 0 | S21: RTS 19/ II | T21: RTS 19/ II | U21: 0.327 | V21: =ROUND(E21*U21,2) -> 19.34 | X21: Práce | AG21: POL1_1
C22: rýha pro kanalizaci : | AG22: VV | AH22: 0
C23: (8,45*3,50)*2 | E23: 59.15 | AG23: VV | AH23: 0
A24: 5 | B24: 151401501R00 | C24: Přepažení rozepření - příložné - hl. do 4 m | D24: m3 | E24: 32.5325 | F24: 36.6 | G24: =ROUND(E24*F24,2) -> 1190.69 | I24: =ROUND(E24*H24,2) -> 0 | K24: =ROUND(E24*J24,2) -> 0 | L24: 21 | M24: =G24*(1+L24/100) -> 1440.7349 | N24: 0 | O24: =ROUND(E24*N24,2) -> 0 | P24: 0 | Q24: =ROUND(E24*P24,2) -> 0 | S24: RTS 19/ II | T24: RTS 19/ II | U24: 0.039 | V24: =ROUND(E24*U24,2) -> 1.27 | X24: Práce | AG24: POL1_1
C25: rýha pro kanalizaci : | AG25: VV | AH25: 0
C26: 8,45*1,10*3,50 | E26: 32.53 | AG26: VV | AH26: 0
A27: 6 | B27: 161101102R00 | C27: Svislé přemístění výkopku z hor.1-4 do 4,0 m | D27: m3 | E27: 32.5325 | F27: 64 | G27: =ROUND(E27*F27,2) -> 2082.08 | I27: =ROUND(E27*H27,2) -> 0 | K27: =ROUND(E27*J27,2) -> 0 | L27: 21 | M27: =G27*(1+L27/100) -> 2519.3168 | N27: 0 | O27: =ROUND(E27*N27,2) -> 0 | P27: 0 | Q27: =ROUND(E27*P27,2) -> 0 | S27: RTS 19/ II | T27: RTS 19/ II | U27: 0.519 | V27: =ROUND(E27*U27,2) -> 16.88 | X27: Práce | AG27: POL1_1
C28: rýha pro kanalizaci : | AG28: VV | AH28: 0
C29: 8,45*1,10*3,50 | E29: 32.53 | AG29: VV | AH29: 0
A30: 7 | B30: 162701105R00 | C30: Vodorovné přemístění výkopku z hor.1-4 do 10000 m | D30: m3 | E30: 5.3911 | F30: 215.5 | G30: =ROUND(E30*F30,2) -> 1161.78 | I30: =ROUND(E30*H30,2) -> 0 | K30: =ROUND(E30*J30,2) -> 0 | L30: 21 | M30: =G30*(1+L30/100) -> 1405.7538 | N30: 0 | O30: =ROUND(E30*N30,2) -> 0 | P30: 0 | Q30: =ROUND(E30*P30,2) -> 0 | S30: RTS 19/ II | T30: RTS 19/ II | U30: 0.011 | V30: =ROUND(E30*U30,2) -> 0.06 | X30: Práce | AG30: POL1_1
C31: odvoz přebytečné zeminy na skládku : | AG31: VV | AH31: 0
C32: 8,45*1,10*0,58 | E32: 5.39 | AG32: VV | AH32: 0
A33: 8 | B33: 167101102R00 | C33: Nakládání výkopku z hor.1-4 v množství nad 100 m3 | D33: m3 | E33: 5.3911 | F33: 61 | G33: =ROUND(E33*F33,2) -> 328.86 | I33: =ROUND(E33*H33,2) -> 0 | K33: =ROUND(E33*J33,2) -> 0 | L33: 21 | M33: =G33*(1+L33/100) -> 397.9206 | N33: 0 | O33: =ROUND(E33*N33,2) -> 0 | P33: 0 | Q33: =ROUND(E33*P33,2) -> 0 | S33: RTS 19/ II | T33: RTS 19/ II | U33: 0.053 | V33: =ROUND(E33*U33,2) -> 0.29 | X33: Práce | AG33: POL1_1
C34: odvoz přebytečné zeminy na skládku : | AG34: VV | AH34: 0
C35: 8,45*1,10*0,58 | E35: 5.39 | AG35: VV | AH35: 0
A36: 9 | B36: 171201201R00 | C36: Uložení sypaniny na skl.-modelace na výšku přes 2m | D36: m3 | E36: 5.3911 | F36: 15.1 | G36: =ROUND(E36*F36,2) -> 81.41 | I36: =ROUND(E36*H36,2) -> 0 | K36: =ROUND(E36*J36,2) -> 0 | L36: 21 | M36: =G36*(1+L36/100) -> 98.5061 | N36: 0 | O36: =ROUND(E36*N36,2) -> 0 | P36: 0 | Q36: =ROUND(E36*P36,2) -> 0 | S36: RTS 19/ II | T36: RTS 19/ II | U36: 0.009 | V36: =ROUND(E36*U36,2) -> 0.05 | X36: Práce | AG36: POL1_1
C37: odvoz přebytečné zeminy na skládku : | AG37: VV | AH37: 0
C38: 8,45*1,10*0,58 | E38: 5.39 | AG38: VV | AH38: 0
A39: 10 | B39: 174101101R00 | C39: Zásyp jam, rýh, šachet se zhutněním | D39: m3 | E39: 27.1414 | F39: 169 | G39: =ROUND(E39*F39,2) -> 4586.9 | I39: =ROUND(E39*H39,2) -> 0 | K39: =ROUND(E39*J39,2) -> 0 | L39: 21 | M39: =G39*(1+L39/100) -> 5550.149 | N39: 0 | O39: =ROUND(E39*N39,2) -> 0 | P39: 0 | Q39: =ROUND(E39*P39,2) -> 0 | S39: RTS 19/ II | T39: RTS 19/ II | U39: 0.202 | V39: =ROUND(E39*U39,2) -> 5.48 | X39: Práce | AG39: POL1_1
C40: zásyp zbylého výkopu vykopanou zeminou : | AG40: VV | AH40: 0
C41: 8,45*1,10*(3,50-0,58) | E41: 27.14 | AG41: VV | AH41: 0
A42: 11 | B42: 199000005R00 | C42: Poplatek za skládku zeminy 1- 4 | D42: t | E42: 10.2431 | F42: 285 | G42: =ROUND(E42*F42,2) -> 2919.28 | I42: =ROUND(E42*H42,2) -> 0 | K42: =ROUND(E42*J42,2) -> 0 | L42: 21 | M42: =G42*(1+L42/100) -> 3532.3288 | N42: 0 | O42: =ROUND(E42*N42,2) -> 0 | P42: 0 | Q42: =ROUND(E42*P42,2) -> 0 | S42: RTS 19/ II | T42: RTS 19/ II | U42: 0 | V42: =ROUND(E42*U42,2) -> 0 | X42: Práce | AG42: POL1_1
...

Sheet IO 730 IO 730 Pol
A1: Položkový rozpočet | AG1: #TypZaznamu#
A2: S: | B2: 2409.2 | C2: Český technologický park Brno, zóna C - objekty D, E, F - infrastruktura | AG2: STA
A3: O: | B3: IO 730 | C3: Vodovod - řady | AC3: STA | AG3: OBJ
A4: R: | B4: IO 730 | C4: Vodovod - řady | AG4: ROZ
A6: P.č. | B6: Číslo položky | C6: Název položky | D6: MJ | E6: Množství | F6: Cena / MJ | G6: Celkem | H6: Dodávka | I6: Dodávka celk. | J6: Montáž | K6: Montáž celk. | L6: DPH | M6: Cena s DPH | N6: Hmotnost / MJ | O6: Hmotnost celk.(t) | P6: Dem. hmotnost / MJ | Q6: Dem. hmotnost celk.(t) | R6: Ceník | S6: Cen. soustava / platnost | T6: Cenová úroveň | U6: Nhod / MJ | V6: Nhod celk. | W6: Dodavatel | X6: Typ položky
A8: Díl: | B8: 1 | C8: Zemní práce | G8: =SUMIF(AG9:AG57,"<>NOR",G9:G57) -> 178881.35 | I8: =SUM(I9:I57) -> 0 | K8: =SUM(K9:K57) -> 0 | M8: =SUM(M9:M57) -> 216446.43 | O8: =SUM(O9:O57) -> 60.59 | Q8: =SUM(Q9:Q57) -> 0 | V8: =SUM(V9:V57) -> 337.75 | AG8: DIL
A9: 1 | B9: 132201219R00 | C9: Přípl.za lepivost,hloubení rýh 200cm,hor.3,STROJNĚ | D9: m3 | E9: 85.0476 | F9: 39.6 | G9: =ROUND(E9*F9,2) -> 3367.88 | I9: =ROUND(E9*H9,2) -> 0 | K9: =ROUND(E9*J9,2) -> 0 | L9: 21 | M9: =G9*(1+L9/100) -> 4075.1348 | N9: 0 | O9: =ROUND(E9*N9,2) -> 0 | P9: 0 | Q9: =ROUND(E9*P9,2) -> 0 | S9: RTS 19/ II | T9: RTS 19/ II | U9: 0.084 | V9: =ROUND(E9*U9,2) -> 7.14 | X9: Práce | AG9: POL1_1
C10: vodovodní řad V1 : | AG10: VV | AH10: 0
C11: Začátek provozního součtu | AG11: VV
C12: 64,43*1,10*2,40 | E12: 170.0952 | AG12: VV | AH12: 2
C13: Konec provozního součtu | AG13: VV
C14: 170,0952/2 | E14: 85.0476 | AG14: VV | AH14: 0
A15: 2 | B15: 132201211R00 | C15: Hloubení rýh š.do 200 cm hor.3 do 100 m3,STROJNĚ | D15: m3 | E15: 170.0952 | F15: 214.5 | G15: =ROUND(E15*F15,2) -> 36485.42 | I15: =ROUND(E15*H15,2) -> 0 | K15: =ROUND(E15*J15,2) -> 0 | L15: 21 | M15: =G15*(1+L15/100) -> 44147.358 | N15: 0 | O15: =ROUND(E15*N15,2) -> 0 | P15: 0 | Q15: =ROUND(E15*P15,2) -> 0 | S15: RTS 19/ II | T15: RTS 19/ II | U15: 0.222 | V15: =ROUND(E15*U15,2) -> 37.76 | X15: Práce | AG15: POL1_1
C16: vodovodní řad V1 : | AG16: VV | AH16: 0
C17: 64,43*1,10*2,40 | E17: 170.1 | AG17: VV | AH17: 0
A18: 3 | B18: 151101101R00 | C18: Pažení a rozepření stěn rýh - příložné - hl. do 2m | D18: m2 | E18: 309.264 | F18: 77.25 | G18: =ROUND(E18*F18,2) -> 23890.64 | I18: =ROUND(E18*H18,2) -> 0 | K18: =ROUND(E18*J18,2) -> 0 | L18: 21 | M18: =G18*(1+L18/100) -> 28907.674 | N18: 0.00099 | O18: =ROUND(E18*N18,2) -> 0.31 | P18: 0 | Q18: =ROUND(E18*P18,2) -> 0 | S18: RTS 19/ II | T18: RTS 19/ II | U18: 0.236 | V18: =ROUND(E18*U18,2) -> 72.99 | X18: Práce | AG18: POL1_1
C19: vodovodní řad V1 : | AG19: VV | AH19: 0
C20: (64,43*2,40)*2 | E20: 309.26 | AG20: VV | AH20: 0
A21: 4 | B21: 151101111R00 | C21: Odstranění pažení stěn rýh - příložné - hl. do 2 m | D21: m2 | E21: 309.264 | F21: 38.63 | G21: =ROUND(E21*F21,2) -> 11946.87 | I21: =ROUND(E21*H21,2) -> 0 | K21: =ROUND(E21*J21,2) -> 0 | L21: 21 | M21: =G21*(1+L21/100) -> 14455.713 | N21: 0 | O21: =ROUND(E21*N21,2) -> 0 | P21: 0 | Q21: =ROUND(E21*P21,2) -> 0 | S21: RTS 19/ II | T21: RTS 19/ II | U21: 0.07 | V21: =ROUND(E21*U21,2) -> 21.65 | X21: Práce | AG21: POL1_1
C22: vodovodní řad V1 : | AG22: VV | AH22: 0
C23: (64,43*2,40)*2 | E23: 309.26 | AG23: VV | AH23: 0
A24: 5 | B24: 151401501R00 | C24: Přepažení rozepření - příložné - hl. do 4 m | D24: m3 | E24: 170.0952 | F24: 36.6 | G24: =ROUND(E24*F24,2) -> 6225.48 | I24: =ROUND(E24*H24,2) -> 0 | K24: =ROUND(E24*J24,2) -> 0 | L24: 21 | M24: =G24*(1+L24/100) -> 7532.8308 | N24: 0 | O24: =ROUND(E24*N24,2) -> 0 | P24: 0 | Q24: =ROUND(E24*P24,2) -> 0 | S24: RTS 19/ II | T24: RTS 19/ II | U24: 0.039 | V24: =ROUND(E24*U24,2) -> 6.63 | X24: Práce | AG24: POL1_1
C25: vodovodní řad V1 : | AG25: VV | AH25: 0
C26: 64,43*1,10*2,40 | E26: 170.1 | AG26: VV | AH26: 0
A27: 6 | B27: 161101102R00 | C27: Svislé přemístění výkopku z hor.1-4 do 4,0 m | D27: m3 | E27: 170.0952 | F27: 64 | G27: =ROUND(E27*F27,2) -> 10886.09 | I27: =ROUND(E27*H27,2) -> 0 | K27: =ROUND(E27*J27,2) -> 0 | L27: 21 | M27: =G27*(1+L27/100) -> 13172.169 | N27: 0 | O27: =ROUND(E27*N27,2) -> 0 | P27: 0 | Q27: =ROUND(E27*P27,2) -> 0 | S27: RTS 19/ II | T27: RTS 19/ II | U27: 0.519 | V27: =ROUND(E27*U27,2) -> 88.28 | X27: Práce | AG27: POL1_0
C28: vodovodní řad V1 : | AG28: VV | AH28: 0
C29: 64,43*1,10*2,40 | E29: 170.1 | AG29: VV | AH29: 0
A30: 7 | B30: 162701105R00 | C30: Vodorovné přemístění výkopku z hor.1-4 do 10000 m | D30: m3 | E30: 38.9802 | F30: 215.5 | G30: =ROUND(E30*F30,2) -> 8400.23 | I30: =ROUND(E30*H30,2) -> 0 | K30: =ROUND(E30*J30,2) -> 0 | L30: 21 | M30: =G30*(1+L30/100) -> 10164.278 | N30: 0 | O30: =ROUND(E30*N30,2) -> 0 | P30: 0 | Q30: =ROUND(E30*P30,2) -> 0 | S30: RTS 19/ II | T30: RTS 19/ II | U30: 0.011 | V30: =ROUND(E30*U30,2) -> 0.43 | X30: Práce | AG30: POL1_1
C31: odvoz přebytečné zeminy na skládku : | AG31: VV | AH31: 0
C32: 64,43*1,10*0,55 | E32: 38.98 | AG32: VV | AH32: 0
A33: 8 | B33: 167101101R00 | C33: Nakládání výkopku z hor.1-4 v množství do 100 m3 | D33: m3 | E33: 38.9802 | F33: 68.96 | G33: =ROUND(E33*F33,2) -> 2688.07 | I33: =ROUND(E33*H33,2) -> 0 | K33: =ROUND(E33*J33,2) -> 0 | L33: 21 | M33: =G33*(1+L33/100) -> 3252.5647 | N33: 0 | O33: =ROUND(E33*N33,2) -> 0 | P33: 0 | Q33: =ROUND(E33*P33,2) -> 0 | S33: RTS 19/ II | T33: RTS 19/ II | U33: 0.652 | V33: =ROUND(E33*U33,2) -> 25.42 | X33: Práce | AG33: POL1_1
C34: odvoz přebytečné zeminy na skládku : | AG34: VV | AH34: 0
C35: 64,43*1,10*0,55 | E35: 38.98 | AG35: VV | AH35: 0
A36: 9 | B36: 171201201R00 | C36: Uložení sypaniny na skl.-modelace na výšku přes 2m | D36: m3 | E36: 38.9802 | F36: 15.1 | G36: =ROUND(E36*F36,2) -> 588.6 | I36: =ROUND(E36*H36,2) -> 0 | K36: =ROUND(E36*J36,2) -> 0 | L36: 21 | M36: =G36*(1+L36/100) -> 712.206 | N36: 0 | O36: =ROUND(E36*N36,2) -> 0 | P36: 0 | Q36: =ROUND(E36*P36,2) -> 0 | S36: RTS 19/ II | T36: RTS 19/ II | U36: 0.009 | V36: =ROUND(E36*U36,2) -> 0.35 | X36: Práce | AG36: POL1_1
C37: odvoz přebytečné zeminy na skládku : | AG37: VV | AH37: 0
C38: 64,43*1,10*0,55 | E38: 38.98 | AG38: VV | AH38: 0
A39: 10 | B39: 174101101R00 | C39: Zásyp jam, rýh, šachet se zhutněním | D39: m3 | E39: 131.1151 | F39: 169 | G39: =ROUND(E39*F39,2) -> 22158.45 | I39: =ROUND(E39*H39,2) -> 0 | K39: =ROUND(E39*J39,2) -> 0 | L39: 21 | M39: =G39*(1+L39/100) -> 26811.725 | N39: 0 | O39: =ROUND(E39*N39,2) -> 0 | P39: 0 | Q39: =ROUND(E39*P39,2) -> 0 | S39: RTS 19/ II | T39: RTS 19/ II | U39: 0.202 | V39: =ROUND(E39*U39,2) -> 26.49 | X39: Práce | AG39: POL1_1
C40: vodovodní řad V1 : | AG40: VV | AH40: 0
C41: zásyp zbylého výkopu vykopanou zeminou : | AG41: VV | AH41: 0
C42: 64,43*1,10*(2,40-0,55) | E42: 131.12 | AG42: VV | AH42: 0
...

Sheet IO 754a IO 754a Pol
A1: Položkový rozpočet | AG1: #TypZaznamu#
A2: S: | B2: 2409.2 | C2: Český technologický park Brno, zóna C - objekty D, E, F - infrastruktura | AG2: STA
A3: O: | B3: IO 754a | C3: Venkovní osvětlení - objekt D | AC3: STA | AG3: OBJ
A4: R: | B4: IO 754a | C4: Venkovní osvětlení - objekt D | AG4: ROZ
A6: P.č. | B6: Číslo položky | C6: Název položky | D6: MJ | E6: Množství | F6: Cena / MJ | G6: Celkem | H6: Dodávka | I6: Dodávka celk. | J6: Montáž | K6: Montáž celk. | L6: DPH | M6: Cena s DPH | N6: Hmotnost / MJ | O6: Hmotnost celk.(t) | P6: Dem. hmotnost / MJ | Q6: Dem. hmotnost celk.(t) | R6: Ceník | S6: Cen. soustava / platnost | T6: Cenová úroveň | U6: Nhod / MJ | V6: Nhod celk. | W6: Dodavatel | X6: Typ položky
A8: Díl: | B8: M21 | C8: Elektromontáže | G8: =SUMIF(AG9:AG12,"<>NOR",G9:G12) -> 239575.9 | I8: =SUM(I9:I12) -> 0 | K8: =SUM(K9:K12) -> 0 | M8: =SUM(M9:M12) -> 289886.84 | O8: =SUM(O9:O12) -> 0 | Q8: =SUM(Q9:Q12) -> 0 | V8: =SUM(V9:V12) -> 0 | AG8: DIL
A9: 1 | B9: 210-001 | C9: D+M kabel CYKY 5x16 | D9: m | E9: 360 | F9: 362.1 | G9: =ROUND(E9*F9,2) -> 130356 | I9: =ROUND(E9*H9,2) -> 0 | K9: =ROUND(E9*J9,2) -> 0 | L9: 21 | M9: =G9*(1+L9/100) -> 157730.76 | N9: 0 | O9: =ROUND(E9*N9,2) -> 0 | P9: 0 | Q9: =ROUND(E9*P9,2) -> 0 | S9: Vlastní | T9: Indiv | U9: 0 | V9: =ROUND(E9*U9,2) -> 0 | X9: Práce | AG9: POL1_1
A10: 2 | B10: 210-002 | C10: D+M rozpínací skříň RS1 kompletní provedení | D10: kus | E10: 1 | F10: 29740.4 | G10: =ROUND(E10*F10,2) -> 29740.4 | I10: =ROUND(E10*H10,2) -> 0 | K10: =ROUND(E10*J10,2) -> 0 | L10: 21 | M10: =G10*(1+L10/100) -> 35985.884 | N10: 0 | O10: =ROUND(E10*N10,2) -> 0 | P10: 0 | Q10: =ROUND(E10*P10,2) -> 0 | S10: Vlastní | T10: Indiv | U10: 0 | V10: =ROUND(E10*U10,2) -> 0 | X10: Práce | AG10: POL1_1
A11: 3 | B11: 210-003 | C11: D+M rozpínací skříň RS2 kompletní provedení | D11: kus | E11: 1 | F11: 27907.2 | G11: =ROUND(E11*F11,2) -> 27907.2 | I11: =ROUND(E11*H11,2) -> 0 | K11: =ROUND(E11*J11,2) -> 0 | L11: 21 | M11: =G11*(1+L11/100) -> 33767.712 | N11: 0 | O11: =ROUND(E11*N11,2) -> 0 | P11: 0 | Q11: =ROUND(E11*P11,2) -> 0 | S11: Vlastní | T11: Indiv | U11: 0 | V11: =ROUND(E11*U11,2) -> 0 | X11: Práce | AG11: POL1_1
A12: 4 | B12: 210-004 | C12: D+M rozpínací skříň RS3 kompletní provedení | D12: kus | E12: 1 | F12: 51572.3 | G12: =ROUND(E12*F12,2) -> 51572.3 | I12: =ROUND(E12*H12,2) -> 0 | K12: =ROUND(E12*J12,2) -> 0 | L12: 21 | M12: =G12*(1+L12/100) -> 62402.483 | N12: 0 | O12: =ROUND(E12*N12,2) -> 0 | P12: 0 | Q12: =ROUND(E12*P12,2) -> 0 | S12: Vlastní | T12: Indiv | U12: 0 | V12: =ROUND(E12*U12,2) -> 0 | X12: Práce | AG12: POL1_1
A13: Díl: | B13: M21.M | C13: Ostatní | G13: =SUMIF(AG14:AG16,"<>NOR",G14:G16) -> 42702.3 | I13: =SUM(I14:I16) -> 0 | K13: =SUM(K14:K16) -> 0 | M13: =SUM(M14:M16) -> 51669.783 | O13: =SUM(O14:O16) -> 0 | Q13: =SUM(Q14:Q16) -> 0 | V13: =SUM(V14:V16) -> 0 | AG13: DIL
A14: 5 | B14: 211-001 | C14: Revize a prohlídky zařízení | D14: kpl. | E14: 1 | F14: 12408.7 | G14: =ROUND(E14*F14,2) -> 12408.7 | I14: =ROUND(E14*H14,2) -> 0 | K14: =ROUND(E14*J14,2) -> 0 | L14: 21 | M14: =G14*(1+L14/100) -> 15014.527 | N14: 0 | O14: =ROUND(E14*N14,2) -> 0 | P14: 0 | Q14: =ROUND(E14*P14,2) -> 0 | S14: Vlastní | T14: Indiv | U14: 0 | V14: =ROUND(E14*U14,2) -> 0 | X14: Práce | AG14: POL1_1
A15: 6 | B15: 211-002 | C15: Dohledání napojovacích bodů | D15: kpl. | E15: 1 | F15: 15000 | G15: =ROUND(E15*F15,2) -> 15000 | I15: =ROUND(E15*H15,2) -> 0 | K15: =ROUND(E15*J15,2) -> 0 | L15: 21 | M15: =G15*(1+L15/100) -> 18150 | N15: 0 | O15: =ROUND(E15*N15,2) -> 0 | P15: 0 | Q15: =ROUND(E15*P15,2) -> 0 | S15: Vlastní | T15: Indiv | U15: 0 | V15: =ROUND(E15*U15,2) -> 0 | X15: Práce | AG15: POL1_1
A16: 7 | B16: 211-003 | C16: Vytyčení stávajících sítí | D16: kpl. | E16: 1 | F16: 15293.6 | G16: =ROUND(E16*F16,2) -> 15293.6 | I16: =ROUND(E16*H16,2) -> 0 | K16: =ROUND(E16*J16,2) -> 0 | L16: 21 | M16: =G16*(1+L16/100) -> 18505.256 | N16: 0 | O16: =ROUND(E16*N16,2) -> 0 | P16: 0 | Q16: =ROUND(E16*P16,2) -> 0 | S16: Vlastní | T16: Indiv | U16: 0 | V16: =ROUND(E16*U16,2) -> 0 | X16: Práce | AG16: POL1_1
A17: Díl: | B17: M23 | C17: Montáže potrubí | G17: =SUMIF(AG18:AG30,"<>NOR",G18:G30) -> 99103.4 | I17: =SUM(I18:I30) -> 0 | K17: =SUM(K18:K30) -> 0 | M17: =SUM(M18:M30) -> 119915.11 | O17: =SUM(O18:O30) -> 0.15 | Q17: =SUM(Q18:Q30) -> 0 | V17: =SUM(V18:V30) -> 51.2 | AG17: DIL
A18: 8 | B18: 230-004 | C18: D+M zemnící pásek FeZn 30/4 | D18: m | E18: 410 | F18: 143.5 | G18: =ROUND(E18*F18,2) -> 58835 | I18: =ROUND(E18*H18,2) -> 0 | K18: =ROUND(E18*J18,2) -> 0 | L18: 21 | M18: =G18*(1+L18/100) -> 71190.35 | N18: 0 | O18: =ROUND(E18*N18,2) -> 0 | P18: 0 | Q18: =ROUND(E18*P18,2) -> 0 | S18: Vlastní | T18: Indiv | U18: 0 | V18: =ROUND(E18*U18,2) -> 0 | X18: Práce | AG18: POL1_1
A19: 9 | B19: 230191008R00 | C19: Uložení chráničky ve výkopu PE 63x5,8mm | D19: m | E19: 360 | F19: 51.5 | G19: =ROUND(E19*F19,2) -> 18540 | I19: =ROUND(E19*H19,2) -> 0 | K19: =ROUND(E19*J19,2) -> 0 | L19: 21 | M19: =G19*(1+L19/100) -> 22433.4 | N19: 0 | O19: =ROUND(E19*N19,2) -> 0 | P19: 0 | Q19: =ROUND(E19*P19,2) -> 0 | S19: RTS 19/ II | T19: RTS 19/ II | U19: 0.12 | V19: =ROUND(E19*U19,2) -> 43.2 | X19: Práce | AG19: POL1_9
C20: chránička DN63 : | AG20: VV | AH20: 0
C21: 360,00 | E21: 360 | AG21: VV | AH21: 0
A22: 10 | B22: 230191018R00 | C22: Uložení chráničky ve výkopu PE 110x10,0 mm | D22: m | E22: 40 | F22: 54.7 | G22: =ROUND(E22*F22,2) -> 2188 | I22: =ROUND(E22*H22,2) -> 0 | K22: =ROUND(E22*J22,2) -> 0 | L22: 21 | M22: =G22*(1+L22/100) -> 2647.48 | N22: 0 | O22: =ROUND(E22*N22,2) -> 0 | P22: 0 | Q22: =ROUND(E22*P22,2) -> 0 | S22: RTS 19/ II | T22: RTS 19/ II | U22: 0.2 | V22: =ROUND(E22*U22,2) -> 8 | X22: Práce | AG22: POL1_9
C23: chránička DN110 : | AG23: VV | AH23: 0
C24: 40,00 | E24: 40 | AG24: VV | AH24: 0
A25: 11 | B25: 3457114702 | C25: Trubka kabelová chránička KOPOFLEX KF 09063 | D25: m | E25: 396 | F25: 40.8 | G25: =ROUND(E25*F25,2) -> 16156.8 | I25: =ROUND(E25*H25,2) -> 0 | K25: =ROUND(E25*J25,2) -> 0 | L25: 21 | M25: =G25*(1+L25/100) -> 19549.728 | N25: 0.00031 | O25: =ROUND(E25*N25,2) -> 0.12 | P25: 0 | Q25: =ROUND(E25*P25,2) -> 0 | R25: SPCM | S25: RTS 19/ II | T25: RTS 19/ II | U25: 0 | V25: =ROUND(E25*U25,2) -> 0 | X25: Specifikace | AG25: POL3_9
C26: chránička DN63 : | AG26: VV | AH26: 0
C27: 360,00*1,10 | E27: 396 | AG27: VV | AH27: 0
A28: 12 | B28: 3457114705 | C28: Trubka kabelová chránička KOPOFLEX KF 09110 | D28: m | E28: 44 | F28: 76.9 | G28: =ROUND(E28*F28,2) -> 3383.6 | I28: =ROUND(E28*H28,2) -> 0 | K28: =ROUND(E28*J28,2) -> 0 | L28: 21 | M28: =G28*(1+L28/100) -> 4094.156 | N28: 0.00069 | O28: =ROUND(E28*N28,2) -> 0.03 | P28: 0 | Q28: =ROUND(E28*P28,2) -> 0 | R28: SPCM | S28: RTS 19/ II | T28: RTS 19/ II | U28: 0 | V28: =ROUND(E28*U28,2) -> 0 | X28: Specifikace | AG28: POL3_9
C29: chránička DN110 : | AG29: VV | AH29: 0
C30: 40,00*1,10 | E30: 44 | AG30: VV | AH30: 0
A31: Díl: | B31: M23.4 | C31: Venkovní osvětlení | G31: =SUMIF(AG32:AG47,"<>NOR",G32:G47) -> 188757.9 | I31: =SUM(I32:I47) -> 0 | K31: =SUM(K32:K47) -> 0 | M31: =SUM(M32:M47) -> 228397.06 | O31: =SUM(O32:O47) -> 0 | Q31: =SUM(Q32:Q47) -> 0 | V31: =SUM(V32:V47) -> 0 | AG31: DIL
A32: 13 | B32: 234-001 | C32: D+M svítidlo VO1 vč.stožáru, výzbroje a uložení výbojkové svítidlo 70W na sloup v.6 m | D32: kus | E32: 1 | F32: 23150 | G32: =ROUND(E32*F32,2) -> 23150 | I32: =ROUND(E32*H32,2) -> 0 | K32: =ROUND(E32*J32,2) -> 0 | L32: 21 | M32: =G32*(1+L32/100) -> 28011.5 | N32: 0 | O32: =ROUND(E32*N32,2) -> 0 | P32: 0 | Q32: =ROUND(E32*P32,2) -> 0 | S32: Vlastní | T32: Indiv | U32: 0 | V32: =ROUND(E32*U32,2) -> 0 | X32: Práce | AG32: POL1_1
C33: 1,00 | E33: 1 | AG33: VV | AH33: 0
A34: 14 | B34: 234-002 | C34: D+M svítidlo VO2 vč.stožáru, výzbroje a uložení výbojkové svítidlo 70W na sloup v.6 m | D34: kus | E34: 1 | F34: 23150 | G34: =ROUND(E34*F34,2) -> 23150 | I34: =ROUND(E34*H34,2) -> 0 | K34: =ROUND(E34*J34,2) -> 0 | L34: 21 | M34: =G34*(1+L34/100) -> 28011.5 | N34: 0 | O34: =ROUND(E34*N34,2) -> 0 | P34: 0 | Q34: =ROUND(E34*P34,2) -> 0 | S34: Vlastní | T34: Indiv | U34: 0 | V34: =ROUND(E34*U34,2) -> 0 | X34: Práce | AG34: POL1_1
C35: 1,00 | E35: 1 | AG35: VV | AH35: 0
A36: 15 | B36: 234-003 | C36: D+M svítidlo VO3 vč.stožáru, výzbroje a uložení výbojkové svítidlo 70W na sloup v.6 m | D36: kus | E36: 2 | F36: 23150 | G36: =ROUND(E36*F36,2) -> 46300 | I36: =ROUND(E36*H36,2) -> 0 | K36: =ROUND(E36*J36,2) -> 0 | L36: 21 | M36: =G36*(1+L36/100) -> 56023 | N36: 0 | O36: =ROUND(E36*N36,2) -> 0 | P36: 0 | Q36: =ROUND(E36*P36,2) -> 0 | S36: Vlastní | T36: Indiv | U36: 0 | V36: =ROUND(E36*U36,2) -> 0 | X36: Práce | AG36: POL1_1
C37: 2,00 | E37: 2 | AG37: VV | AH37: 0
A38: 16 | B38: 234-004 | C38: D+M svítidlo VO4 vč.stožáru, výzbroje a uložení výbojkové svítidlo 70W na sloup v.6 m | D38: kus | E38: 1 | F38: 23150 | G38: =ROUND(E38*F38,2) -> 23150 | I38: =ROUND(E38*H38,2) -> 0 | K38: =ROUND(E38*J38,2) -> 0 | L38: 21 | M38: =G38*(1+L38/100) -> 28011.5 | N38: 0 | O38: =ROUND(E38*N38,2) -> 0 | P38: 0 | Q38: =ROUND(E38*P38,2) -> 0 | S38: Vlastní | T38: Indiv | U38: 0 | V38: =ROUND(E38*U38,2) -> 0 | X38: Práce | AG38: POL1_1
C39: 1,00 | E39: 1 | AG39: VV | AH39: 0
A40: 17 | B40: 234-005 | C40: D+M svítidlo VO5 vč.stožáru, výzbroje a uložení výbojkové svítidlo 70W na sloup v.6 m | D40: kus | E40: 1 | F40: 23150 | G40: =ROUND(E40*F40,2) -> 23150 | I40: =ROUND(E40*H40,2) -> 0 | K40: =ROUND(E40*J40,2) -> 0 | L40: 21 | M40: =G40*(1+L40/100) -> 28011.5 | N40: 0 | O40: =ROUND(E40*N40,2) -> 0 | P40: 0 | Q40: =ROUND(E40*P40,2) -> 0 | S40: Vlastní | T40: Indiv | U40: 0 | V40: =ROUND(E40*U40,2) -> 0 | X40: Práce | AG40: POL1_1
C41: 1,00 | E41: 1 | AG41: VV | AH41: 0
A42: 18 | B42: 234-006 | C42: D+M svítidlo VO6 vč.stožáru, výzbroje a uložení výbojkové svítidlo 70W na sloup v.6 m | D42: kus | E42: 1 | F42: 23150 | G42: =ROUND(E42*F42,2) -> 23150 | I42: =ROUND(E42*H42,2) -> 0 | K42: =ROUND(E42*J42,2) -> 0 | L42: 21 | M42: =G42*(1+L42/100) -> 28011.5 | N42: 0 | O42: =ROUND(E42*N42,2) -> 0 | P42: 0 | Q42: =ROUND(E42*P42,2) -> 0 | S42: Vlastní | T42: Indiv | U42: 0 | V42: =ROUND(E42*U42,2) -> 0 | X42: Práce | AG42: POL1_1
...

Sheet IO 760b IO 760b Pol
A1: Položkový rozpočet | AG1: #TypZaznamu#
A2: S: | B2: 2409.2 | C2: Český technologický park Brno, zóna C - objekty D, E, F - infrastruktura | AG2: STA
A3: O: | B3: IO 760b | C3: Přeložka SLP - optika VUT | AC3: STA | AG3: OBJ
A4: R: | B4: IO 760b | C4: Přeložka SLP - optika VUT | AG4: ROZ
A6: P.č. | B6: Číslo položky | C6: Název položky | D6: MJ | E6: Množství | F6: Cena / MJ | G6: Celkem | H6: Dodávka | I6: Dodávka celk. | J6: Montáž | K6: Montáž celk. | L6: DPH | M6: Cena s DPH | N6: Hmotnost / MJ | O6: Hmotnost celk.(t) | P6: Dem. hmotnost / MJ | Q6: Dem. hmotnost celk.(t) | R6: Ceník | S6: Cen. soustava / platnost | T6: Cenová úroveň | U6: Nhod / MJ | V6: Nhod celk. | W6: Dodavatel | X6: Typ položky
A8: Díl: | B8: M21 | C8: Elektromontáže | G8: =SUMIF(AG9:AG24,"<>NOR",G9:G24) -> 316395.75 | I8: =SUM(I9:I24) -> 0 | K8: =SUM(K9:K24) -> 0 | M8: =SUM(M9:M24) -> 382838.86 | O8: =SUM(O9:O24) -> 0 | Q8: =SUM(Q9:Q24) -> 0 | V8: =SUM(V9:V24) -> 0 | AG8: DIL
A9: 1 | B9: 210-001 | C9: D+M Kabelová šachta s víkem ref. ZEKAN M1080 | D9: kus | E9: 1 | F9: 25845.6 | G9: =ROUND(E9*F9,2) -> 25845.6 | I9: =ROUND(E9*H9,2) -> 0 | K9: =ROUND(E9*J9,2) -> 0 | L9: 21 | M9: =G9*(1+L9/100) -> 31273.176 | N9: 0 | O9: =ROUND(E9*N9,2) -> 0 | P9: 0 | Q9: =ROUND(E9*P9,2) -> 0 | S9: Vlastní | T9: Indiv | U9: 0 | V9: =ROUND(E9*U9,2) -> 0 | X9: Práce | AG9: POL1_1
A10: 2 | B10: 210-002 | C10: D+M Chránička HDPE zemní tlustostěnná 32/27mm zodolněná, osazená 4x trubičkou 10/8mm | D10: m | E10: 75 | F10: 112.16 | G10: =ROUND(E10*F10,2) -> 8412 | I10: =ROUND(E10*H10,2) -> 0 | K10: =ROUND(E10*J10,2) -> 0 | L10: 21 | M10: =G10*(1+L10/100) -> 10178.52 | N10: 0 | O10: =ROUND(E10*N10,2) -> 0 | P10: 0 | Q10: =ROUND(E10*P10,2) -> 0 | S10: Vlastní | T10: Indiv | U10: 0 | V10: =ROUND(E10*U10,2) -> 0 | X10: Práce | AG10: POL1_1
A11: 3 | B11: 210-003 | C11: D+M Chránička HDPE zemní tlustostěnná 32/27mm bez mikrotrubiček | D11: m | E11: 75 | F11: 91.57 | G11: =ROUND(E11*F11,2) -> 6867.75 | I11: =ROUND(E11*H11,2) -> 0 | K11: =ROUND(E11*J11,2) -> 0 | L11: 21 | M11: =G11*(1+L11/100) -> 8309.9775 | N11: 0 | O11: =ROUND(E11*N11,2) -> 0 | P11: 0 | Q11: =ROUND(E11*P11,2) -> 0 | S11: Vlastní | T11: Indiv | U11: 0 | V11: =ROUND(E11*U11,2) -> 0 | X11: Práce | AG11: POL1_1
A12: 4 | B12: 210-004 | C12: D+M optický kabel 96VLÁKEN SM G.652D | D12: m | E12: 85 | F12: 67.44 | G12: =ROUND(E12*F12,2) -> 5732.4 | I12: =ROUND(E12*H12,2) -> 0 | K12: =ROUND(E12*J12,2) -> 0 | L12: 21 | M12: =G12*(1+L12/100) -> 6936.204 | N12: 0 | O12: =ROUND(E12*N12,2) -> 0 | P12: 0 | Q12: =ROUND(E12*P12,2) -> 0 | S12: Vlastní | T12: Indiv | U12: 0 | V12: =ROUND(E12*U12,2) -> 0 | X12: Práce | AG12: POL1_1
A13: 5 | B13: 210-005 | C13: D+M optická spojka PRO 96 VLÁKEN (REF. SX-FOSC-D-96) | D13: kus | E13: 2 | F13: 11400 | G13: =ROUND(E13*F13,2) -> 22800 | I13: =ROUND(E13*H13,2) -> 0 | K13: =ROUND(E13*J13,2) -> 0 | L13: 21 | M13: =G13*(1+L13/100) -> 27588 | N13: 0 | O13: =ROUND(E13*N13,2) -> 0 | P13: 0 | Q13: =ROUND(E13*P13,2) -> 0 | S13: Vlastní | T13: Indiv | U13: 0 | V13: =ROUND(E13*U13,2) -> 0 | X13: Práce | AG13: POL1_1
A14: 6 | B14: 210-006 | C14: D+M Utěsnění prostupů v šachtě | D14: kus | E14: 1 | F14: 1000 | G14: =ROUND(E14*F14,2) -> 1000 | I14: =ROUND(E14*H14,2) -> 0 | K14: =ROUND(E14*J14,2) -> 0 | L14: 21 | M14: =G14*(1+L14/100) -> 1210 | N14: 0 | O14: =ROUND(E14*N14,2) -> 0 | P14: 0 | Q14: =ROUND(E14*P14,2) -> 0 | S14: Vlastní | T14: Indiv | U14: 0 | V14: =ROUND(E14*U14,2) -> 0 | X14: Práce | AG14: POL1_1
A15: 7 | B15: 210-007 | C15: D+M Optický svár včetně měřícího protokolu | D15: kus | E15: 192 | F15: 594 | G15: =ROUND(E15*F15,2) -> 114048 | I15: =ROUND(E15*H15,2) -> 0 | K15: =ROUND(E15*J15,2) -> 0 | L15: 21 | M15: =G15*(1+L15/100) -> 137998.08 | N15: 0 | O15: =ROUND(E15*N15,2) -> 0 | P15: 0 | Q15: =ROUND(E15*P15,2) -> 0 | S15: Vlastní | T15: Indiv | U15: 0 | V15: =ROUND(E15*U15,2) -> 0 | X15: Práce | AG15: POL1_1
A16: 8 | B16: 210-008 | C16: Demontáž stávajícího kabelu z rušené přípojky | D16: kus | E16: 1 | F16: 12000 | G16: =ROUND(E16*F16,2) -> 12000 | I16: =ROUND(E16*H16,2) -> 0 | K16: =ROUND(E16*J16,2) -> 0 | L16: 21 | M16: =G16*(1+L16/100) -> 14520 | N16: 0 | O16: =ROUND(E16*N16,2) -> 0 | P16: 0 | Q16: =ROUND(E16*P16,2) -> 0 | S16: Vlastní | T16: Indiv | U16: 0 | V16: =ROUND(E16*U16,2) -> 0 | X16: Práce | AG16: POL1_1
A17: 9 | B17: 210-009 | C17: D+M 1401-XR Ball marker telekomunikace | D17: kus | E17: 5 | F17: 246 | G17: =ROUND(E17*F17,2) -> 1230 | I17: =ROUND(E17*H17,2) -> 0 | K17: =ROUND(E17*J17,2) -> 0 | L17: 21 | M17: =G17*(1+L17/100) -> 1488.3 | N17: 0 | O17: =ROUND(E17*N17,2) -> 0 | P17: 0 | Q17: =ROUND(E17*P17,2) -> 0 | S17: Vlastní | T17: Indiv | U17: 0 | V17: =ROUND(E17*U17,2) -> 0 | X17: Práce | AG17: POL1_1
A18: 10 | B18: 210-010 | C18: Vytýčení stávajícího vedení | D18: kus | E18: 1 | F18: 14400 | G18: =ROUND(E18*F18,2) -> 14400 | I18: =ROUND(E18*H18,2) -> 0 | K18: =ROUND(E18*J18,2) -> 0 | L18: 21 | M18: =G18*(1+L18/100) -> 17424 | N18: 0 | O18: =ROUND(E18*N18,2) -> 0 | P18: 0 | Q18: =ROUND(E18*P18,2) -> 0 | S18: Vlastní | T18: Indiv | U18: 0 | V18: =ROUND(E18*U18,2) -> 0 | X18: Práce | AG18: POL1_1
A19: 11 | B19: 210-011 | C19: Geodetické práce - skutečný stav | D19: kus | E19: 1 | F19: 10820 | G19: =ROUND(E19*F19,2) -> 10820 | I19: =ROUND(E19*H19,2) -> 0 | K19: =ROUND(E19*J19,2) -> 0 | L19: 21 | M19: =G19*(1+L19/100) -> 13092.2 | N19: 0 | O19: =ROUND(E19*N19,2) -> 0 | P19: 0 | Q19: =ROUND(E19*P19,2) -> 0 | S19: Vlastní | T19: Indiv | U19: 0 | V19: =ROUND(E19*U19,2) -> 0 | X19: Práce | AG19: POL1_1
A20: 12 | B20: 210-012 | C20: Koordinační činnosti s provozovatelem přeložky | D20: kus | E20: 1 | F20: 3360 | G20: =ROUND(E20*F20,2) -> 3360 | I20: =ROUND(E20*H20,2) -> 0 | K20: =ROUND(E20*J20,2) -> 0 | L20: 21 | M20: =G20*(1+L20/100) -> 4065.6 | N20: 0 | O20: =ROUND(E20*N20,2) -> 0 | P20: 0 | Q20: =ROUND(E20*P20,2) -> 0 | S20: Vlastní | T20: Indiv | U20: 0 | V20: =ROUND(E20*U20,2) -> 0 | X20: Práce | AG20: POL1_1
... A24: 16 | B24: 210-016 | C24: Ostaní nespecifikované činnosti nutné pro úspěšnou realizaci díla | D24: kus | E24: 1 | F24: 14400 | G24: =ROUND(E24*F24,2) -> 14400 | I24: =ROUND(E24*H24,2) -> 0 | K24: =ROUND(E24*J24,2) -> 0 | L24: 21 | M24: =G24*(1+L24/100) -> 17424 | N24: 0 | O24: =ROUND(E24*N24,2) -> 0 | P24: 0 | Q24: =ROUND(E24*P24,2) -> 0 | S24: Vlastní | T24: Indiv | U24: 0 | V24: =ROUND(E24*U24,2) -> 0 | X24: Práce | AG24: POL1_1
A25: Díl: | B25: M46 | C25: Zemní práce při montážích | G25: =SUMIF(AG26:AG27,"<>NOR",G26:G27) -> 18690 | I25: =SUM(I26:I27) -> 0 | K25: =SUM(K26:K27) -> 0 | M25: =SUM(M26:M27) -> 22614.9 | O25: =SUM(O26:O27) -> 0 | Q25: =SUM(Q26:Q27) -> 0 | V25: =SUM(V26:V27) -> 0 | AG25: DIL
A26: 17 | B26: 460-001 | C26: Zemní výkopové práce pro šachtu zekan M1080 | D26: kus | E26: 1 | F26: 1680 | G26: =ROUND(E26*F26,2) -> 1680 | I26: =ROUND(E26*H26,2) -> 0 | K26: =ROUND(E26*J26,2) -> 0 | L26: 21 | M26: =G26*(1+L26/100) -> 2032.8 | N26: 0 | O26: =ROUND(E26*N26,2) -> 0 | P26: 0 | Q26: =ROUND(E26*P26,2) -> 0 | S26: Vlastní | T26: Indiv | U26: 0 | V26: =ROUND(E26*U26,2) -> 0 | X26: Práce | AG26: POL1_1
A27: 18 | B27: 460-002 | C27: Zemní práce 60/35 včetně kabelového lože zákrytových desek, záhozu a úpravy povrchu | D27: m | E27: 75 | F27: 226.8 | G27: =ROUND(E27*F27,2) -> 17010 | I27: =ROUND(E27*H27,2) -> 0 | K27: =ROUND(E27*J27,2) -> 0 | L27: 21 | M27: =G27*(1+L27/100) -> 20582.1 | N27: 0 | O27: =ROUND(E27*N27,2) -> 0 | P27: 0 | Q27: =ROUND(E27*P27,2) -> 0 | S27: Vlastní | T27: Indiv | U27: 0 | V27: =ROUND(E27*U27,2) -> 0 | X27: Práce | AG27: POL1_1
AE28: 15 | AF28: 21 | AG28: DPH
B29: Celkem | G29: =G8+G25 -> 335085.75 | AE29: =SUMIF(L7:L27,AE28,G7:G27) -> 0 | AF29: =SUMIF(L7:L27,AF28,G7:G27) -> 335085.75 | AG29: SUM
A32: Poznámky uchazeče k zadání
AG33: POPUZIV
AG39: END

Sheet IO 730a IO 730a Pol
A1: Položkový rozpočet | AG1: #TypZaznamu#
A2: S: | B2: 2409.2 | C2: Český technologický park Brno, zóna C - objekty D, E, F - infrastruktura | AG2: STA
A3: O: | B3: IO 730a | C3: Vodovod - přípojka D | AC3: STA | AG3: OBJ
A4: R: | B4: IO 730a | C4: Vodovod - přípojka D | AG4: ROZ
A6: P.č. | B6: Číslo položky | C6: Název položky | D6: MJ | E6: Množství | F6: Cena / MJ | G6: Celkem | H6: Dodávka | I6: Dodávka celk. | J6: Montáž | K6: Montáž celk. | L6: DPH | M6: Cena s DPH | N6: Hmotnost / MJ | O6: Hmotnost celk.(t) | P6: Dem. hmotnost / MJ | Q6: Dem. hmotnost celk.(t) | R6: Ceník | S6: Cen. soustava / platnost | T6: Cenová úroveň | U6: Nhod / MJ | V6: Nhod celk. | W6: Dodavatel | X6: Typ položky
A8: Díl: | B8: 1 | C8: Zemní práce | G8: =SUMIF(AG9:AG57,"<>NOR",G9:G57) -> 14289.36 | I8: =SUM(I9:I57) -> 0 | K8: =SUM(K9:K57) -> 0 | M8: =SUM(M9:M57) -> 17290.126 | O8: =SUM(O9:O57) -> 5.82 | Q8: =SUM(Q9:Q57) -> 0 | V8: =SUM(V9:V57) -> 26.04 | AG8: DIL
A9: 1 | B9: 132201219R00 | C9: Přípl.za lepivost,hloubení rýh 200cm,hor.3,STROJNĚ | D9: m3 | E9: 6.138 | F9: 39.6 | G9: =ROUND(E9*F9,2) -> 243.06 | I9: =ROUND(E9*H9,2) -> 0 | K9: =ROUND(E9*J9,2) -> 0 | L9: 21 | M9: =G9*(1+L9/100) -> 294.1026 | N9: 0 | O9: =ROUND(E9*N9,2) -> 0 | P9: 0 | Q9: =ROUND(E9*P9,2) -> 0 | S9: RTS 19/ II | T9: RTS 19/ II | U9: 0.084 | V9: =ROUND(E9*U9,2) -> 0.52 | X9: Práce | AG9: POL1_1
C10: přípojka D : | AG10: VV | AH10: 0
C11: Začátek provozního součtu | AG11: VV
C12: 6,20*1,10*1,80 | E12: 12.276 | AG12: VV | AH12: 2
C13: Konec provozního součtu | AG13: VV
C14: 12,2760/2 | E14: 6.138 | AG14: VV | AH14: 0
A15: 2 | B15: 132201211R00 | C15: Hloubení rýh š.do 200 cm hor.3 do 100 m3,STROJNĚ | D15: m3 | E15: 12.276 | F15: 214.5 | G15: =ROUND(E15*F15,2) -> 2633.2 | I15: =ROUND(E15*H15,2) -> 0 | K15: =ROUND(E15*J15,2) -> 0 | L15: 21 | M15: =G15*(1+L15/100) -> 3186.172 | N15: 0 | O15: =ROUND(E15*N15,2) -> 0 | P15: 0 | Q15: =ROUND(E15*P15,2) -> 0 | S15: RTS 19/ II | T15: RTS 19/ II | U15: 0.222 | V15: =ROUND(E15*U15,2) -> 2.73 | X15: Práce | AG15: POL1_1
C16: přípojka D : | AG16: VV | AH16: 0
C17: 6,20*1,10*1,80 | E17: 12.28 | AG17: VV | AH17: 0
A18: 3 | B18: 151101101R00 | C18: Pažení a rozepření stěn rýh - příložné - hl. do 2m | D18: m2 | E18: 22.32 | F18: 77.25 | G18: =ROUND(E18*F18,2) -> 1724.22 | I18: =ROUND(E18*H18,2) -> 0 | K18: =ROUND(E18*J18,2) -> 0 | L18: 21 | M18: =G18*(1+L18/100) -> 2086.3062 | N18: 0.00099 | O18: =ROUND(E18*N18,2) -> 0.02 | P18: 0 | Q18: =ROUND(E18*P18,2) -> 0 | S18: RTS 19/ II | T18: RTS 19/ II | U18: 0.236 | V18: =ROUND(E18*U18,2) -> 5.27 | X18: Práce | AG18: POL1_1
C19: přípojka D : | AG19: VV | AH19: 0
C20: (6,20*1,80)*2 | E20: 22.32 | AG20: VV | AH20: 0
A21: 4 | B21: 151101111R00 | C21: Odstranění pažení stěn rýh - příložné - hl. do 2 m | D21: m2 | E21: 22.32 | F21: 38.63 | G21: =ROUND(E21*F21,2) -> 862.22 | I21: =ROUND(E21*H21,2) -> 0 | K21: =ROUND(E21*J21,2) -> 0 | L21: 21 | M21: =G21*(1+L21/100) -> 1043.2862 | N21: 0 | O21: =ROUND(E21*N21,2) -> 0 | P21: 0 | Q21: =ROUND(E21*P21,2) -> 0 | S21: RTS 19/ II | T21: RTS 19/ II | U21: 0.07 | V21: =ROUND(E21*U21,2) -> 1.56 | X21: Práce | AG21: POL1_1
C22: přípojka D : | AG22: VV | AH22: 0
C23: (6,20*1,80)*2 | E23: 22.32 | AG23: VV | AH23: 0
A24: 5 | B24: 151401501R00 | C24: Přepažení rozepření - příložné - hl. do 4 m | D24: m3 | E24: 12.276 | F24: 36.6 | G24: =ROUND(E24*F24,2) -> 449.3 | I24: =ROUND(E24*H24,2) -> 0 | K24: =ROUND(E24*J24,2) -> 0 | L24: 21 | M24: =G24*(1+L24/100) -> 543.653 | N24: 0 | O24: =ROUND(E24*N24,2) -> 0 | P24: 0 | Q24: =ROUND(E24*P24,2) -> 0 | S24: RTS 19/ II | T24: RTS 19/ II | U24: 0.039 | V24: =ROUND(E24*U24,2) -> 0.48 | X24: Práce | AG24: POL1_1
C25: přípojka D : | AG25: VV | AH25: 0
C26: 6,20*1,10*1,80 | E26: 12.28 | AG26: VV | AH26: 0
A27: 6 | B27: 161101102R00 | C27: Svislé přemístění výkopku z hor.1-4 do 4,0 m | D27: m3 | E27: 12.276 | F27: 64 | G27: =ROUND(E27*F27,2) -> 785.66 | I27: =ROUND(E27*H27,2) -> 0 | K27: =ROUND(E27*J27,2) -> 0 | L27: 21 | M27: =G27*(1+L27/100) -> 950.6486 | N27: 0 | O27: =ROUND(E27*N27,2) -> 0 | P27: 0 | Q27: =ROUND(E27*P27,2) -> 0 | S27: RTS 19/ II | T27: RTS 19/ II | U27: 0.519 | V27: =ROUND(E27*U27,2) -> 6.37 | X27: Práce | AG27: POL1_0
C28: přípojka D : | AG28: VV | AH28: 0
